[2025-01-16T19:21:45.064+0000] {processor.py:186} INFO - Started process (PID=110) to work on /opt/airflow/dags/test.py
[2025-01-16T19:21:45.067+0000] {processor.py:914} INFO - Processing file /opt/airflow/dags/test.py for tasks to queue
[2025-01-16T19:21:45.074+0000] {logging_mixin.py:190} INFO - [2025-01-16T19:21:45.073+0000] {dagbag.py:588} INFO - Filling up the DagBag from /opt/airflow/dags/test.py
[2025-01-16T19:21:45.734+0000] {logging_mixin.py:190} INFO - [2025-01-16T19:21:45.717+0000] {templater.py:94} ERROR - Failed to resolve template field '_sql'
Traceback (most recent call last):
  File "/home/airflow/.local/lib/python3.12/site-packages/airflow/template/templater.py", line 92, in resolve_template_files
    setattr(self, field, env.loader.get_source(env, content)[0])  # type: ignore
                         ^^^^^^^^^^^^^^^^^^^^^^^^^^^^^^^^^^^
  File "/home/airflow/.local/lib/python3.12/site-packages/jinja2/loaders.py", line 207, in get_source
    raise TemplateNotFound(template)
jinja2.exceptions.TemplateNotFound: test.sql
[2025-01-16T19:21:45.761+0000] {processor.py:925} INFO - DAG(s) 'test' retrieved from /opt/airflow/dags/test.py
[2025-01-16T19:21:45.998+0000] {logging_mixin.py:190} INFO - [2025-01-16T19:21:45.997+0000] {dag.py:3239} INFO - Sync 1 DAGs
[2025-01-16T19:21:46.100+0000] {logging_mixin.py:190} INFO - [2025-01-16T19:21:46.099+0000] {dag.py:4180} INFO - Setting next_dagrun for test to None, run_after=None
[2025-01-16T19:21:46.243+0000] {processor.py:208} INFO - Processing /opt/airflow/dags/test.py took 1.206 seconds
[2025-01-16T19:22:17.133+0000] {processor.py:186} INFO - Started process (PID=120) to work on /opt/airflow/dags/test.py
[2025-01-16T19:22:17.160+0000] {processor.py:914} INFO - Processing file /opt/airflow/dags/test.py for tasks to queue
[2025-01-16T19:22:17.196+0000] {logging_mixin.py:190} INFO - [2025-01-16T19:22:17.190+0000] {dagbag.py:588} INFO - Filling up the DagBag from /opt/airflow/dags/test.py
[2025-01-16T19:22:18.747+0000] {logging_mixin.py:190} INFO - [2025-01-16T19:22:18.723+0000] {templater.py:94} ERROR - Failed to resolve template field '_sql'
Traceback (most recent call last):
  File "/home/airflow/.local/lib/python3.12/site-packages/airflow/template/templater.py", line 92, in resolve_template_files
    setattr(self, field, env.loader.get_source(env, content)[0])  # type: ignore
                         ^^^^^^^^^^^^^^^^^^^^^^^^^^^^^^^^^^^
  File "/home/airflow/.local/lib/python3.12/site-packages/jinja2/loaders.py", line 207, in get_source
    raise TemplateNotFound(template)
jinja2.exceptions.TemplateNotFound: test.sql
[2025-01-16T19:22:18.768+0000] {processor.py:925} INFO - DAG(s) 'test' retrieved from /opt/airflow/dags/test.py
[2025-01-16T19:22:19.064+0000] {logging_mixin.py:190} INFO - [2025-01-16T19:22:19.063+0000] {dag.py:3239} INFO - Sync 1 DAGs
[2025-01-16T19:22:19.148+0000] {logging_mixin.py:190} INFO - [2025-01-16T19:22:19.148+0000] {dag.py:4180} INFO - Setting next_dagrun for test to None, run_after=None
[2025-01-16T19:22:19.445+0000] {processor.py:208} INFO - Processing /opt/airflow/dags/test.py took 2.344 seconds
[2025-01-16T19:22:50.020+0000] {processor.py:186} INFO - Started process (PID=131) to work on /opt/airflow/dags/test.py
[2025-01-16T19:22:50.044+0000] {processor.py:914} INFO - Processing file /opt/airflow/dags/test.py for tasks to queue
[2025-01-16T19:22:50.070+0000] {logging_mixin.py:190} INFO - [2025-01-16T19:22:50.068+0000] {dagbag.py:588} INFO - Filling up the DagBag from /opt/airflow/dags/test.py
[2025-01-16T19:22:50.742+0000] {logging_mixin.py:190} INFO - [2025-01-16T19:22:50.736+0000] {templater.py:94} ERROR - Failed to resolve template field '_sql'
Traceback (most recent call last):
  File "/home/airflow/.local/lib/python3.12/site-packages/airflow/template/templater.py", line 92, in resolve_template_files
    setattr(self, field, env.loader.get_source(env, content)[0])  # type: ignore
                         ^^^^^^^^^^^^^^^^^^^^^^^^^^^^^^^^^^^
  File "/home/airflow/.local/lib/python3.12/site-packages/jinja2/loaders.py", line 207, in get_source
    raise TemplateNotFound(template)
jinja2.exceptions.TemplateNotFound: test.sql
[2025-01-16T19:22:50.892+0000] {processor.py:925} INFO - DAG(s) 'test' retrieved from /opt/airflow/dags/test.py
[2025-01-16T19:22:50.987+0000] {logging_mixin.py:190} INFO - [2025-01-16T19:22:50.987+0000] {dag.py:3239} INFO - Sync 1 DAGs
[2025-01-16T19:22:51.047+0000] {logging_mixin.py:190} INFO - [2025-01-16T19:22:51.046+0000] {dag.py:4180} INFO - Setting next_dagrun for test to None, run_after=None
[2025-01-16T19:22:51.258+0000] {processor.py:208} INFO - Processing /opt/airflow/dags/test.py took 1.358 seconds
[2025-01-16T19:23:22.192+0000] {processor.py:186} INFO - Started process (PID=142) to work on /opt/airflow/dags/test.py
[2025-01-16T19:23:22.216+0000] {processor.py:914} INFO - Processing file /opt/airflow/dags/test.py for tasks to queue
[2025-01-16T19:23:22.283+0000] {logging_mixin.py:190} INFO - [2025-01-16T19:23:22.279+0000] {dagbag.py:588} INFO - Filling up the DagBag from /opt/airflow/dags/test.py
[2025-01-16T19:23:23.659+0000] {logging_mixin.py:190} INFO - [2025-01-16T19:23:23.644+0000] {templater.py:94} ERROR - Failed to resolve template field '_sql'
Traceback (most recent call last):
  File "/home/airflow/.local/lib/python3.12/site-packages/airflow/template/templater.py", line 92, in resolve_template_files
    setattr(self, field, env.loader.get_source(env, content)[0])  # type: ignore
                         ^^^^^^^^^^^^^^^^^^^^^^^^^^^^^^^^^^^
  File "/home/airflow/.local/lib/python3.12/site-packages/jinja2/loaders.py", line 207, in get_source
    raise TemplateNotFound(template)
jinja2.exceptions.TemplateNotFound: test.sql
[2025-01-16T19:23:23.680+0000] {processor.py:925} INFO - DAG(s) 'test' retrieved from /opt/airflow/dags/test.py
[2025-01-16T19:23:23.940+0000] {logging_mixin.py:190} INFO - [2025-01-16T19:23:23.939+0000] {dag.py:3239} INFO - Sync 1 DAGs
[2025-01-16T19:23:24.080+0000] {logging_mixin.py:190} INFO - [2025-01-16T19:23:24.079+0000] {dag.py:4180} INFO - Setting next_dagrun for test to None, run_after=None
[2025-01-16T19:23:24.275+0000] {processor.py:208} INFO - Processing /opt/airflow/dags/test.py took 2.286 seconds
[2025-01-16T19:23:54.546+0000] {processor.py:186} INFO - Started process (PID=153) to work on /opt/airflow/dags/test.py
[2025-01-16T19:23:54.547+0000] {processor.py:914} INFO - Processing file /opt/airflow/dags/test.py for tasks to queue
[2025-01-16T19:23:54.550+0000] {logging_mixin.py:190} INFO - [2025-01-16T19:23:54.550+0000] {dagbag.py:588} INFO - Filling up the DagBag from /opt/airflow/dags/test.py
[2025-01-16T19:23:54.739+0000] {logging_mixin.py:190} INFO - [2025-01-16T19:23:54.738+0000] {templater.py:94} ERROR - Failed to resolve template field '_sql'
Traceback (most recent call last):
  File "/home/airflow/.local/lib/python3.12/site-packages/airflow/template/templater.py", line 92, in resolve_template_files
    setattr(self, field, env.loader.get_source(env, content)[0])  # type: ignore
                         ^^^^^^^^^^^^^^^^^^^^^^^^^^^^^^^^^^^
  File "/home/airflow/.local/lib/python3.12/site-packages/jinja2/loaders.py", line 207, in get_source
    raise TemplateNotFound(template)
jinja2.exceptions.TemplateNotFound: test.sql
[2025-01-16T19:23:54.742+0000] {processor.py:925} INFO - DAG(s) 'test' retrieved from /opt/airflow/dags/test.py
[2025-01-16T19:23:54.770+0000] {logging_mixin.py:190} INFO - [2025-01-16T19:23:54.770+0000] {dag.py:3239} INFO - Sync 1 DAGs
[2025-01-16T19:23:54.784+0000] {logging_mixin.py:190} INFO - [2025-01-16T19:23:54.784+0000] {dag.py:4180} INFO - Setting next_dagrun for test to None, run_after=None
[2025-01-16T19:23:55.300+0000] {processor.py:208} INFO - Processing /opt/airflow/dags/test.py took 0.761 seconds
[2025-01-16T19:24:25.796+0000] {processor.py:186} INFO - Started process (PID=164) to work on /opt/airflow/dags/test.py
[2025-01-16T19:24:25.805+0000] {processor.py:914} INFO - Processing file /opt/airflow/dags/test.py for tasks to queue
[2025-01-16T19:24:25.841+0000] {logging_mixin.py:190} INFO - [2025-01-16T19:24:25.838+0000] {dagbag.py:588} INFO - Filling up the DagBag from /opt/airflow/dags/test.py
[2025-01-16T19:24:27.089+0000] {logging_mixin.py:190} INFO - [2025-01-16T19:24:27.080+0000] {templater.py:94} ERROR - Failed to resolve template field '_sql'
Traceback (most recent call last):
  File "/home/airflow/.local/lib/python3.12/site-packages/airflow/template/templater.py", line 92, in resolve_template_files
    setattr(self, field, env.loader.get_source(env, content)[0])  # type: ignore
                         ^^^^^^^^^^^^^^^^^^^^^^^^^^^^^^^^^^^
  File "/home/airflow/.local/lib/python3.12/site-packages/jinja2/loaders.py", line 207, in get_source
    raise TemplateNotFound(template)
jinja2.exceptions.TemplateNotFound: test.sql
[2025-01-16T19:24:27.116+0000] {processor.py:925} INFO - DAG(s) 'test' retrieved from /opt/airflow/dags/test.py
[2025-01-16T19:24:27.296+0000] {logging_mixin.py:190} INFO - [2025-01-16T19:24:27.292+0000] {dag.py:3239} INFO - Sync 1 DAGs
[2025-01-16T19:24:27.361+0000] {logging_mixin.py:190} INFO - [2025-01-16T19:24:27.360+0000] {dag.py:4180} INFO - Setting next_dagrun for test to None, run_after=None
[2025-01-16T19:24:28.367+0000] {processor.py:208} INFO - Processing /opt/airflow/dags/test.py took 2.637 seconds
[2025-01-16T19:24:58.507+0000] {processor.py:186} INFO - Started process (PID=175) to work on /opt/airflow/dags/test.py
[2025-01-16T19:24:58.511+0000] {processor.py:914} INFO - Processing file /opt/airflow/dags/test.py for tasks to queue
[2025-01-16T19:24:58.518+0000] {logging_mixin.py:190} INFO - [2025-01-16T19:24:58.517+0000] {dagbag.py:588} INFO - Filling up the DagBag from /opt/airflow/dags/test.py
[2025-01-16T19:24:58.818+0000] {logging_mixin.py:190} INFO - [2025-01-16T19:24:58.815+0000] {templater.py:94} ERROR - Failed to resolve template field '_sql'
Traceback (most recent call last):
  File "/home/airflow/.local/lib/python3.12/site-packages/airflow/template/templater.py", line 92, in resolve_template_files
    setattr(self, field, env.loader.get_source(env, content)[0])  # type: ignore
                         ^^^^^^^^^^^^^^^^^^^^^^^^^^^^^^^^^^^
  File "/home/airflow/.local/lib/python3.12/site-packages/jinja2/loaders.py", line 207, in get_source
    raise TemplateNotFound(template)
jinja2.exceptions.TemplateNotFound: test.sql
[2025-01-16T19:24:58.824+0000] {processor.py:925} INFO - DAG(s) 'test' retrieved from /opt/airflow/dags/test.py
[2025-01-16T19:24:59.137+0000] {logging_mixin.py:190} INFO - [2025-01-16T19:24:59.137+0000] {dag.py:3239} INFO - Sync 1 DAGs
[2025-01-16T19:25:00.336+0000] {logging_mixin.py:190} INFO - [2025-01-16T19:25:00.336+0000] {dag.py:4180} INFO - Setting next_dagrun for test to None, run_after=None
[2025-01-16T19:25:00.710+0000] {processor.py:208} INFO - Processing /opt/airflow/dags/test.py took 2.223 seconds
[2025-01-16T19:25:30.973+0000] {processor.py:186} INFO - Started process (PID=186) to work on /opt/airflow/dags/test.py
[2025-01-16T19:25:30.980+0000] {processor.py:914} INFO - Processing file /opt/airflow/dags/test.py for tasks to queue
[2025-01-16T19:25:30.993+0000] {logging_mixin.py:190} INFO - [2025-01-16T19:25:30.992+0000] {dagbag.py:588} INFO - Filling up the DagBag from /opt/airflow/dags/test.py
[2025-01-16T19:25:31.856+0000] {logging_mixin.py:190} INFO - [2025-01-16T19:25:31.851+0000] {templater.py:94} ERROR - Failed to resolve template field '_sql'
Traceback (most recent call last):
  File "/home/airflow/.local/lib/python3.12/site-packages/airflow/template/templater.py", line 92, in resolve_template_files
    setattr(self, field, env.loader.get_source(env, content)[0])  # type: ignore
                         ^^^^^^^^^^^^^^^^^^^^^^^^^^^^^^^^^^^
  File "/home/airflow/.local/lib/python3.12/site-packages/jinja2/loaders.py", line 207, in get_source
    raise TemplateNotFound(template)
jinja2.exceptions.TemplateNotFound: test.sql
[2025-01-16T19:25:31.875+0000] {processor.py:925} INFO - DAG(s) 'test' retrieved from /opt/airflow/dags/test.py
[2025-01-16T19:25:31.989+0000] {logging_mixin.py:190} INFO - [2025-01-16T19:25:31.988+0000] {dag.py:3239} INFO - Sync 1 DAGs
[2025-01-16T19:25:33.537+0000] {logging_mixin.py:190} INFO - [2025-01-16T19:25:33.536+0000] {dag.py:4180} INFO - Setting next_dagrun for test to None, run_after=None
[2025-01-16T19:25:33.906+0000] {processor.py:208} INFO - Processing /opt/airflow/dags/test.py took 2.957 seconds
[2025-01-16T19:26:04.888+0000] {processor.py:186} INFO - Started process (PID=197) to work on /opt/airflow/dags/test.py
[2025-01-16T19:26:04.894+0000] {processor.py:914} INFO - Processing file /opt/airflow/dags/test.py for tasks to queue
[2025-01-16T19:26:04.906+0000] {logging_mixin.py:190} INFO - [2025-01-16T19:26:04.904+0000] {dagbag.py:588} INFO - Filling up the DagBag from /opt/airflow/dags/test.py
[2025-01-16T19:26:05.762+0000] {logging_mixin.py:190} INFO - [2025-01-16T19:26:05.758+0000] {templater.py:94} ERROR - Failed to resolve template field '_sql'
Traceback (most recent call last):
  File "/home/airflow/.local/lib/python3.12/site-packages/airflow/template/templater.py", line 92, in resolve_template_files
    setattr(self, field, env.loader.get_source(env, content)[0])  # type: ignore
                         ^^^^^^^^^^^^^^^^^^^^^^^^^^^^^^^^^^^
  File "/home/airflow/.local/lib/python3.12/site-packages/jinja2/loaders.py", line 207, in get_source
    raise TemplateNotFound(template)
jinja2.exceptions.TemplateNotFound: test.sql
[2025-01-16T19:26:06.182+0000] {processor.py:925} INFO - DAG(s) 'test' retrieved from /opt/airflow/dags/test.py
[2025-01-16T19:26:06.298+0000] {logging_mixin.py:190} INFO - [2025-01-16T19:26:06.297+0000] {dag.py:3239} INFO - Sync 1 DAGs
[2025-01-16T19:26:06.341+0000] {logging_mixin.py:190} INFO - [2025-01-16T19:26:06.340+0000] {dag.py:4180} INFO - Setting next_dagrun for test to None, run_after=None
[2025-01-16T19:26:06.437+0000] {processor.py:208} INFO - Processing /opt/airflow/dags/test.py took 1.577 seconds
[2025-01-16T19:26:37.243+0000] {processor.py:186} INFO - Started process (PID=208) to work on /opt/airflow/dags/test.py
[2025-01-16T19:26:37.249+0000] {processor.py:914} INFO - Processing file /opt/airflow/dags/test.py for tasks to queue
[2025-01-16T19:26:37.261+0000] {logging_mixin.py:190} INFO - [2025-01-16T19:26:37.259+0000] {dagbag.py:588} INFO - Filling up the DagBag from /opt/airflow/dags/test.py
[2025-01-16T19:26:38.579+0000] {logging_mixin.py:190} INFO - [2025-01-16T19:26:38.575+0000] {templater.py:94} ERROR - Failed to resolve template field '_sql'
Traceback (most recent call last):
  File "/home/airflow/.local/lib/python3.12/site-packages/airflow/template/templater.py", line 92, in resolve_template_files
    setattr(self, field, env.loader.get_source(env, content)[0])  # type: ignore
                         ^^^^^^^^^^^^^^^^^^^^^^^^^^^^^^^^^^^
  File "/home/airflow/.local/lib/python3.12/site-packages/jinja2/loaders.py", line 207, in get_source
    raise TemplateNotFound(template)
jinja2.exceptions.TemplateNotFound: test.sql
[2025-01-16T19:26:38.589+0000] {processor.py:925} INFO - DAG(s) 'test' retrieved from /opt/airflow/dags/test.py
[2025-01-16T19:26:38.672+0000] {logging_mixin.py:190} INFO - [2025-01-16T19:26:38.671+0000] {dag.py:3239} INFO - Sync 1 DAGs
[2025-01-16T19:26:38.744+0000] {logging_mixin.py:190} INFO - [2025-01-16T19:26:38.743+0000] {dag.py:4180} INFO - Setting next_dagrun for test to None, run_after=None
[2025-01-16T19:26:38.837+0000] {processor.py:208} INFO - Processing /opt/airflow/dags/test.py took 1.618 seconds
[2025-01-16T19:27:09.079+0000] {processor.py:186} INFO - Started process (PID=219) to work on /opt/airflow/dags/test.py
[2025-01-16T19:27:09.082+0000] {processor.py:914} INFO - Processing file /opt/airflow/dags/test.py for tasks to queue
[2025-01-16T19:27:09.090+0000] {logging_mixin.py:190} INFO - [2025-01-16T19:27:09.089+0000] {dagbag.py:588} INFO - Filling up the DagBag from /opt/airflow/dags/test.py
[2025-01-16T19:27:09.853+0000] {logging_mixin.py:190} INFO - [2025-01-16T19:27:09.849+0000] {templater.py:94} ERROR - Failed to resolve template field '_sql'
Traceback (most recent call last):
  File "/home/airflow/.local/lib/python3.12/site-packages/airflow/template/templater.py", line 92, in resolve_template_files
    setattr(self, field, env.loader.get_source(env, content)[0])  # type: ignore
                         ^^^^^^^^^^^^^^^^^^^^^^^^^^^^^^^^^^^
  File "/home/airflow/.local/lib/python3.12/site-packages/jinja2/loaders.py", line 207, in get_source
    raise TemplateNotFound(template)
jinja2.exceptions.TemplateNotFound: test.sql
[2025-01-16T19:27:09.872+0000] {processor.py:925} INFO - DAG(s) 'test' retrieved from /opt/airflow/dags/test.py
[2025-01-16T19:27:09.986+0000] {logging_mixin.py:190} INFO - [2025-01-16T19:27:09.985+0000] {dag.py:3239} INFO - Sync 1 DAGs
[2025-01-16T19:27:10.039+0000] {logging_mixin.py:190} INFO - [2025-01-16T19:27:10.039+0000] {dag.py:4180} INFO - Setting next_dagrun for test to None, run_after=None
[2025-01-16T19:27:10.556+0000] {processor.py:208} INFO - Processing /opt/airflow/dags/test.py took 1.501 seconds
[2025-01-16T19:27:41.475+0000] {processor.py:186} INFO - Started process (PID=230) to work on /opt/airflow/dags/test.py
[2025-01-16T19:27:41.477+0000] {processor.py:914} INFO - Processing file /opt/airflow/dags/test.py for tasks to queue
[2025-01-16T19:27:41.482+0000] {logging_mixin.py:190} INFO - [2025-01-16T19:27:41.481+0000] {dagbag.py:588} INFO - Filling up the DagBag from /opt/airflow/dags/test.py
[2025-01-16T19:27:41.821+0000] {logging_mixin.py:190} INFO - [2025-01-16T19:27:41.820+0000] {templater.py:94} ERROR - Failed to resolve template field '_sql'
Traceback (most recent call last):
  File "/home/airflow/.local/lib/python3.12/site-packages/airflow/template/templater.py", line 92, in resolve_template_files
    setattr(self, field, env.loader.get_source(env, content)[0])  # type: ignore
                         ^^^^^^^^^^^^^^^^^^^^^^^^^^^^^^^^^^^
  File "/home/airflow/.local/lib/python3.12/site-packages/jinja2/loaders.py", line 207, in get_source
    raise TemplateNotFound(template)
jinja2.exceptions.TemplateNotFound: test.sql
[2025-01-16T19:27:41.826+0000] {processor.py:925} INFO - DAG(s) 'test' retrieved from /opt/airflow/dags/test.py
[2025-01-16T19:27:41.869+0000] {logging_mixin.py:190} INFO - [2025-01-16T19:27:41.868+0000] {dag.py:3239} INFO - Sync 1 DAGs
[2025-01-16T19:27:42.174+0000] {logging_mixin.py:190} INFO - [2025-01-16T19:27:42.173+0000] {dag.py:4180} INFO - Setting next_dagrun for test to None, run_after=None
[2025-01-16T19:27:42.219+0000] {processor.py:208} INFO - Processing /opt/airflow/dags/test.py took 0.755 seconds
[2025-01-16T19:28:13.150+0000] {processor.py:186} INFO - Started process (PID=241) to work on /opt/airflow/dags/test.py
[2025-01-16T19:28:13.151+0000] {processor.py:914} INFO - Processing file /opt/airflow/dags/test.py for tasks to queue
[2025-01-16T19:28:13.155+0000] {logging_mixin.py:190} INFO - [2025-01-16T19:28:13.155+0000] {dagbag.py:588} INFO - Filling up the DagBag from /opt/airflow/dags/test.py
[2025-01-16T19:28:13.373+0000] {logging_mixin.py:190} INFO - [2025-01-16T19:28:13.372+0000] {templater.py:94} ERROR - Failed to resolve template field '_sql'
Traceback (most recent call last):
  File "/home/airflow/.local/lib/python3.12/site-packages/airflow/template/templater.py", line 92, in resolve_template_files
    setattr(self, field, env.loader.get_source(env, content)[0])  # type: ignore
                         ^^^^^^^^^^^^^^^^^^^^^^^^^^^^^^^^^^^
  File "/home/airflow/.local/lib/python3.12/site-packages/jinja2/loaders.py", line 207, in get_source
    raise TemplateNotFound(template)
jinja2.exceptions.TemplateNotFound: test.sql
[2025-01-16T19:28:13.376+0000] {processor.py:925} INFO - DAG(s) 'test' retrieved from /opt/airflow/dags/test.py
[2025-01-16T19:28:13.621+0000] {logging_mixin.py:190} INFO - [2025-01-16T19:28:13.621+0000] {dag.py:3239} INFO - Sync 1 DAGs
[2025-01-16T19:28:13.642+0000] {logging_mixin.py:190} INFO - [2025-01-16T19:28:13.641+0000] {dag.py:4180} INFO - Setting next_dagrun for test to None, run_after=None
[2025-01-16T19:28:13.676+0000] {processor.py:208} INFO - Processing /opt/airflow/dags/test.py took 0.532 seconds
[2025-01-16T19:28:44.225+0000] {processor.py:186} INFO - Started process (PID=252) to work on /opt/airflow/dags/test.py
[2025-01-16T19:28:44.227+0000] {processor.py:914} INFO - Processing file /opt/airflow/dags/test.py for tasks to queue
[2025-01-16T19:28:44.229+0000] {logging_mixin.py:190} INFO - [2025-01-16T19:28:44.229+0000] {dagbag.py:588} INFO - Filling up the DagBag from /opt/airflow/dags/test.py
[2025-01-16T19:28:44.443+0000] {logging_mixin.py:190} INFO - [2025-01-16T19:28:44.442+0000] {templater.py:94} ERROR - Failed to resolve template field '_sql'
Traceback (most recent call last):
  File "/home/airflow/.local/lib/python3.12/site-packages/airflow/template/templater.py", line 92, in resolve_template_files
    setattr(self, field, env.loader.get_source(env, content)[0])  # type: ignore
                         ^^^^^^^^^^^^^^^^^^^^^^^^^^^^^^^^^^^
  File "/home/airflow/.local/lib/python3.12/site-packages/jinja2/loaders.py", line 207, in get_source
    raise TemplateNotFound(template)
jinja2.exceptions.TemplateNotFound: test.sql
[2025-01-16T19:28:44.446+0000] {processor.py:925} INFO - DAG(s) 'test' retrieved from /opt/airflow/dags/test.py
[2025-01-16T19:28:44.664+0000] {logging_mixin.py:190} INFO - [2025-01-16T19:28:44.663+0000] {dag.py:3239} INFO - Sync 1 DAGs
[2025-01-16T19:28:44.681+0000] {logging_mixin.py:190} INFO - [2025-01-16T19:28:44.680+0000] {dag.py:4180} INFO - Setting next_dagrun for test to None, run_after=None
[2025-01-16T19:28:44.714+0000] {processor.py:208} INFO - Processing /opt/airflow/dags/test.py took 0.494 seconds
[2025-01-16T19:29:14.826+0000] {processor.py:186} INFO - Started process (PID=263) to work on /opt/airflow/dags/test.py
[2025-01-16T19:29:14.828+0000] {processor.py:914} INFO - Processing file /opt/airflow/dags/test.py for tasks to queue
[2025-01-16T19:29:14.833+0000] {logging_mixin.py:190} INFO - [2025-01-16T19:29:14.833+0000] {dagbag.py:588} INFO - Filling up the DagBag from /opt/airflow/dags/test.py
[2025-01-16T19:29:15.284+0000] {logging_mixin.py:190} INFO - [2025-01-16T19:29:15.283+0000] {templater.py:94} ERROR - Failed to resolve template field '_sql'
Traceback (most recent call last):
  File "/home/airflow/.local/lib/python3.12/site-packages/airflow/template/templater.py", line 92, in resolve_template_files
    setattr(self, field, env.loader.get_source(env, content)[0])  # type: ignore
                         ^^^^^^^^^^^^^^^^^^^^^^^^^^^^^^^^^^^
  File "/home/airflow/.local/lib/python3.12/site-packages/jinja2/loaders.py", line 207, in get_source
    raise TemplateNotFound(template)
jinja2.exceptions.TemplateNotFound: test.sql
[2025-01-16T19:29:15.287+0000] {processor.py:925} INFO - DAG(s) 'test' retrieved from /opt/airflow/dags/test.py
[2025-01-16T19:29:15.655+0000] {processor.py:211} ERROR - Got an exception! Propagating...
Traceback (most recent call last):
  File "/home/airflow/.local/lib/python3.12/site-packages/sqlalchemy/engine/base.py", line 3371, in _wrap_pool_connect
    return fn()
           ^^^^
  File "/home/airflow/.local/lib/python3.12/site-packages/sqlalchemy/pool/base.py", line 327, in connect
    return _ConnectionFairy._checkout(self)
           ^^^^^^^^^^^^^^^^^^^^^^^^^^^^^^^^
  File "/home/airflow/.local/lib/python3.12/site-packages/sqlalchemy/pool/base.py", line 894, in _checkout
    fairy = _ConnectionRecord.checkout(pool)
            ^^^^^^^^^^^^^^^^^^^^^^^^^^^^^^^^
  File "/home/airflow/.local/lib/python3.12/site-packages/sqlalchemy/pool/base.py", line 493, in checkout
    rec = pool._do_get()
          ^^^^^^^^^^^^^^
  File "/home/airflow/.local/lib/python3.12/site-packages/sqlalchemy/pool/impl.py", line 145, in _do_get
    with util.safe_reraise():
         ^^^^^^^^^^^^^^^^^^^
  File "/home/airflow/.local/lib/python3.12/site-packages/sqlalchemy/util/langhelpers.py", line 70, in __exit__
    compat.raise_(
  File "/home/airflow/.local/lib/python3.12/site-packages/sqlalchemy/util/compat.py", line 211, in raise_
    raise exception
  File "/home/airflow/.local/lib/python3.12/site-packages/sqlalchemy/pool/impl.py", line 143, in _do_get
    return self._create_connection()
           ^^^^^^^^^^^^^^^^^^^^^^^^^
  File "/home/airflow/.local/lib/python3.12/site-packages/sqlalchemy/pool/base.py", line 273, in _create_connection
    return _ConnectionRecord(self)
           ^^^^^^^^^^^^^^^^^^^^^^^
  File "/home/airflow/.local/lib/python3.12/site-packages/sqlalchemy/pool/base.py", line 388, in __init__
    self.__connect()
  File "/home/airflow/.local/lib/python3.12/site-packages/sqlalchemy/pool/base.py", line 690, in __connect
    with util.safe_reraise():
         ^^^^^^^^^^^^^^^^^^^
  File "/home/airflow/.local/lib/python3.12/site-packages/sqlalchemy/util/langhelpers.py", line 70, in __exit__
    compat.raise_(
  File "/home/airflow/.local/lib/python3.12/site-packages/sqlalchemy/util/compat.py", line 211, in raise_
    raise exception
  File "/home/airflow/.local/lib/python3.12/site-packages/sqlalchemy/pool/base.py", line 686, in __connect
    self.dbapi_connection = connection = pool._invoke_creator(self)
                                         ^^^^^^^^^^^^^^^^^^^^^^^^^^
  File "/home/airflow/.local/lib/python3.12/site-packages/sqlalchemy/engine/create.py", line 574, in connect
    return dialect.connect(*cargs, **cparams)
           ^^^^^^^^^^^^^^^^^^^^^^^^^^^^^^^^^^
  File "/home/airflow/.local/lib/python3.12/site-packages/sqlalchemy/engine/default.py", line 598, in connect
    return self.dbapi.connect(*cargs, **cparams)
           ^^^^^^^^^^^^^^^^^^^^^^^^^^^^^^^^^^^^^
  File "/home/airflow/.local/lib/python3.12/site-packages/psycopg2/__init__.py", line 122, in connect
    conn = _connect(dsn, connection_factory=connection_factory, **kwasync)
           ^^^^^^^^^^^^^^^^^^^^^^^^^^^^^^^^^^^^^^^^^^^^^^^^^^^^^^^^^^^^^^^
psycopg2.OperationalError: could not translate host name "postgres" to address: Temporary failure in name resolution


The above exception was the direct cause of the following exception:

Traceback (most recent call last):
  File "/home/airflow/.local/lib/python3.12/site-packages/airflow/dag_processing/processor.py", line 207, in _run_file_processor
    _handle_dag_file_processing()
  File "/home/airflow/.local/lib/python3.12/site-packages/airflow/dag_processing/processor.py", line 188, in _handle_dag_file_processing
    result: tuple[int, int, int] = dag_file_processor.process_file(
                                   ^^^^^^^^^^^^^^^^^^^^^^^^^^^^^^^^
  File "/home/airflow/.local/lib/python3.12/site-packages/airflow/utils/session.py", line 97, in wrapper
    return func(*args, session=session, **kwargs)
           ^^^^^^^^^^^^^^^^^^^^^^^^^^^^^^^^^^^^^^
  File "/home/airflow/.local/lib/python3.12/site-packages/airflow/dag_processing/processor.py", line 942, in process_file
    serialize_errors = DagFileProcessor.save_dag_to_db(
                       ^^^^^^^^^^^^^^^^^^^^^^^^^^^^^^^^
  File "/home/airflow/.local/lib/python3.12/site-packages/airflow/api_internal/internal_api_call.py", line 166, in wrapper
    return func(*args, **kwargs)
           ^^^^^^^^^^^^^^^^^^^^^
  File "/home/airflow/.local/lib/python3.12/site-packages/airflow/utils/session.py", line 97, in wrapper
    return func(*args, session=session, **kwargs)
           ^^^^^^^^^^^^^^^^^^^^^^^^^^^^^^^^^^^^^^
  File "/home/airflow/.local/lib/python3.12/site-packages/airflow/dag_processing/processor.py", line 982, in save_dag_to_db
    import_errors = DagBag._sync_to_db(dags=dags, processor_subdir=dag_directory, session=session)
                    ^^^^^^^^^^^^^^^^^^^^^^^^^^^^^^^^^^^^^^^^^^^^^^^^^^^^^^^^^^^^^^^^^^^^^^^^^^^^^^
  File "/home/airflow/.local/lib/python3.12/site-packages/airflow/utils/session.py", line 94, in wrapper
    return func(*args, **kwargs)
           ^^^^^^^^^^^^^^^^^^^^^
  File "/home/airflow/.local/lib/python3.12/site-packages/airflow/models/dagbag.py", line 708, in _sync_to_db
    for attempt in run_with_db_retries(logger=log):
                   ^^^^^^^^^^^^^^^^^^^^^^^^^^^^^^^
  File "/home/airflow/.local/lib/python3.12/site-packages/tenacity/__init__.py", line 443, in __iter__
    do = self.iter(retry_state=retry_state)
         ^^^^^^^^^^^^^^^^^^^^^^^^^^^^^^^^^^
  File "/home/airflow/.local/lib/python3.12/site-packages/tenacity/__init__.py", line 376, in iter
    result = action(retry_state)
             ^^^^^^^^^^^^^^^^^^^
  File "/home/airflow/.local/lib/python3.12/site-packages/tenacity/__init__.py", line 418, in exc_check
    raise retry_exc.reraise()
          ^^^^^^^^^^^^^^^^^^^
  File "/home/airflow/.local/lib/python3.12/site-packages/tenacity/__init__.py", line 185, in reraise
    raise self.last_attempt.result()
          ^^^^^^^^^^^^^^^^^^^^^^^^^^
  File "/usr/local/lib/python3.12/concurrent/futures/_base.py", line 449, in result
    return self.__get_result()
           ^^^^^^^^^^^^^^^^^^^
  File "/usr/local/lib/python3.12/concurrent/futures/_base.py", line 401, in __get_result
    raise self._exception
  File "/home/airflow/.local/lib/python3.12/site-packages/airflow/models/dagbag.py", line 721, in _sync_to_db
    _serialize_dag_capturing_errors(dag, session, processor_subdir)
  File "/home/airflow/.local/lib/python3.12/site-packages/airflow/models/dagbag.py", line 686, in _serialize_dag_capturing_errors
    dag_was_updated = SerializedDagModel.write_dag(
                      ^^^^^^^^^^^^^^^^^^^^^^^^^^^^^
  File "/home/airflow/.local/lib/python3.12/site-packages/airflow/utils/session.py", line 94, in wrapper
    return func(*args, **kwargs)
           ^^^^^^^^^^^^^^^^^^^^^
  File "/home/airflow/.local/lib/python3.12/site-packages/airflow/models/serialized_dag.py", line 160, in write_dag
    if session.scalar(
       ^^^^^^^^^^^^^^^
  File "/home/airflow/.local/lib/python3.12/site-packages/sqlalchemy/orm/session.py", line 1747, in scalar
    return self.execute(
           ^^^^^^^^^^^^^
  File "/home/airflow/.local/lib/python3.12/site-packages/sqlalchemy/orm/session.py", line 1716, in execute
    conn = self._connection_for_bind(bind)
           ^^^^^^^^^^^^^^^^^^^^^^^^^^^^^^^
  File "/home/airflow/.local/lib/python3.12/site-packages/sqlalchemy/orm/session.py", line 1555, in _connection_for_bind
    return self._transaction._connection_for_bind(
           ^^^^^^^^^^^^^^^^^^^^^^^^^^^^^^^^^^^^^^^
  File "/home/airflow/.local/lib/python3.12/site-packages/sqlalchemy/orm/session.py", line 750, in _connection_for_bind
    conn = bind.connect()
           ^^^^^^^^^^^^^^
  File "/home/airflow/.local/lib/python3.12/site-packages/sqlalchemy/future/engine.py", line 412, in connect
    return super(Engine, self).connect()
           ^^^^^^^^^^^^^^^^^^^^^^^^^^^^^
  File "/home/airflow/.local/lib/python3.12/site-packages/sqlalchemy/engine/base.py", line 3325, in connect
    return self._connection_cls(self, close_with_result=close_with_result)
           ^^^^^^^^^^^^^^^^^^^^^^^^^^^^^^^^^^^^^^^^^^^^^^^^^^^^^^^^^^^^^^^
  File "/home/airflow/.local/lib/python3.12/site-packages/sqlalchemy/engine/base.py", line 96, in __init__
    else engine.raw_connection()
         ^^^^^^^^^^^^^^^^^^^^^^^
  File "/home/airflow/.local/lib/python3.12/site-packages/sqlalchemy/engine/base.py", line 3404, in raw_connection
    return self._wrap_pool_connect(self.pool.connect, _connection)
           ^^^^^^^^^^^^^^^^^^^^^^^^^^^^^^^^^^^^^^^^^^^^^^^^^^^^^^^
  File "/home/airflow/.local/lib/python3.12/site-packages/sqlalchemy/engine/base.py", line 3374, in _wrap_pool_connect
    Connection._handle_dbapi_exception_noconnection(
  File "/home/airflow/.local/lib/python3.12/site-packages/sqlalchemy/engine/base.py", line 2208, in _handle_dbapi_exception_noconnection
    util.raise_(
  File "/home/airflow/.local/lib/python3.12/site-packages/sqlalchemy/util/compat.py", line 211, in raise_
    raise exception
  File "/home/airflow/.local/lib/python3.12/site-packages/sqlalchemy/engine/base.py", line 3371, in _wrap_pool_connect
    return fn()
           ^^^^
  File "/home/airflow/.local/lib/python3.12/site-packages/sqlalchemy/pool/base.py", line 327, in connect
    return _ConnectionFairy._checkout(self)
           ^^^^^^^^^^^^^^^^^^^^^^^^^^^^^^^^
  File "/home/airflow/.local/lib/python3.12/site-packages/sqlalchemy/pool/base.py", line 894, in _checkout
    fairy = _ConnectionRecord.checkout(pool)
            ^^^^^^^^^^^^^^^^^^^^^^^^^^^^^^^^
  File "/home/airflow/.local/lib/python3.12/site-packages/sqlalchemy/pool/base.py", line 493, in checkout
    rec = pool._do_get()
          ^^^^^^^^^^^^^^
  File "/home/airflow/.local/lib/python3.12/site-packages/sqlalchemy/pool/impl.py", line 145, in _do_get
    with util.safe_reraise():
         ^^^^^^^^^^^^^^^^^^^
  File "/home/airflow/.local/lib/python3.12/site-packages/sqlalchemy/util/langhelpers.py", line 70, in __exit__
    compat.raise_(
  File "/home/airflow/.local/lib/python3.12/site-packages/sqlalchemy/util/compat.py", line 211, in raise_
    raise exception
  File "/home/airflow/.local/lib/python3.12/site-packages/sqlalchemy/pool/impl.py", line 143, in _do_get
    return self._create_connection()
           ^^^^^^^^^^^^^^^^^^^^^^^^^
  File "/home/airflow/.local/lib/python3.12/site-packages/sqlalchemy/pool/base.py", line 273, in _create_connection
    return _ConnectionRecord(self)
           ^^^^^^^^^^^^^^^^^^^^^^^
  File "/home/airflow/.local/lib/python3.12/site-packages/sqlalchemy/pool/base.py", line 388, in __init__
    self.__connect()
  File "/home/airflow/.local/lib/python3.12/site-packages/sqlalchemy/pool/base.py", line 690, in __connect
    with util.safe_reraise():
         ^^^^^^^^^^^^^^^^^^^
  File "/home/airflow/.local/lib/python3.12/site-packages/sqlalchemy/util/langhelpers.py", line 70, in __exit__
    compat.raise_(
  File "/home/airflow/.local/lib/python3.12/site-packages/sqlalchemy/util/compat.py", line 211, in raise_
    raise exception
  File "/home/airflow/.local/lib/python3.12/site-packages/sqlalchemy/pool/base.py", line 686, in __connect
    self.dbapi_connection = connection = pool._invoke_creator(self)
                                         ^^^^^^^^^^^^^^^^^^^^^^^^^^
  File "/home/airflow/.local/lib/python3.12/site-packages/sqlalchemy/engine/create.py", line 574, in connect
    return dialect.connect(*cargs, **cparams)
           ^^^^^^^^^^^^^^^^^^^^^^^^^^^^^^^^^^
  File "/home/airflow/.local/lib/python3.12/site-packages/sqlalchemy/engine/default.py", line 598, in connect
    return self.dbapi.connect(*cargs, **cparams)
           ^^^^^^^^^^^^^^^^^^^^^^^^^^^^^^^^^^^^^
  File "/home/airflow/.local/lib/python3.12/site-packages/psycopg2/__init__.py", line 122, in connect
    conn = _connect(dsn, connection_factory=connection_factory, **kwasync)
           ^^^^^^^^^^^^^^^^^^^^^^^^^^^^^^^^^^^^^^^^^^^^^^^^^^^^^^^^^^^^^^^
sqlalchemy.exc.OperationalError: (psycopg2.OperationalError) could not translate host name "postgres" to address: Temporary failure in name resolution

(Background on this error at: https://sqlalche.me/e/14/e3q8)
[2025-01-16T19:29:45.708+0000] {processor.py:186} INFO - Started process (PID=268) to work on /opt/airflow/dags/test.py
[2025-01-16T19:29:45.709+0000] {processor.py:914} INFO - Processing file /opt/airflow/dags/test.py for tasks to queue
[2025-01-16T19:29:45.712+0000] {logging_mixin.py:190} INFO - [2025-01-16T19:29:45.712+0000] {dagbag.py:588} INFO - Filling up the DagBag from /opt/airflow/dags/test.py
[2025-01-16T19:29:45.872+0000] {logging_mixin.py:190} INFO - [2025-01-16T19:29:45.871+0000] {templater.py:94} ERROR - Failed to resolve template field '_sql'
Traceback (most recent call last):
  File "/home/airflow/.local/lib/python3.12/site-packages/airflow/template/templater.py", line 92, in resolve_template_files
    setattr(self, field, env.loader.get_source(env, content)[0])  # type: ignore
                         ^^^^^^^^^^^^^^^^^^^^^^^^^^^^^^^^^^^
  File "/home/airflow/.local/lib/python3.12/site-packages/jinja2/loaders.py", line 207, in get_source
    raise TemplateNotFound(template)
jinja2.exceptions.TemplateNotFound: test.sql
[2025-01-16T19:29:45.875+0000] {processor.py:925} INFO - DAG(s) 'test' retrieved from /opt/airflow/dags/test.py
[2025-01-16T19:29:46.323+0000] {processor.py:211} ERROR - Got an exception! Propagating...
Traceback (most recent call last):
  File "/home/airflow/.local/lib/python3.12/site-packages/sqlalchemy/engine/base.py", line 3371, in _wrap_pool_connect
    return fn()
           ^^^^
  File "/home/airflow/.local/lib/python3.12/site-packages/sqlalchemy/pool/base.py", line 327, in connect
    return _ConnectionFairy._checkout(self)
           ^^^^^^^^^^^^^^^^^^^^^^^^^^^^^^^^
  File "/home/airflow/.local/lib/python3.12/site-packages/sqlalchemy/pool/base.py", line 894, in _checkout
    fairy = _ConnectionRecord.checkout(pool)
            ^^^^^^^^^^^^^^^^^^^^^^^^^^^^^^^^
  File "/home/airflow/.local/lib/python3.12/site-packages/sqlalchemy/pool/base.py", line 493, in checkout
    rec = pool._do_get()
          ^^^^^^^^^^^^^^
  File "/home/airflow/.local/lib/python3.12/site-packages/sqlalchemy/pool/impl.py", line 145, in _do_get
    with util.safe_reraise():
         ^^^^^^^^^^^^^^^^^^^
  File "/home/airflow/.local/lib/python3.12/site-packages/sqlalchemy/util/langhelpers.py", line 70, in __exit__
    compat.raise_(
  File "/home/airflow/.local/lib/python3.12/site-packages/sqlalchemy/util/compat.py", line 211, in raise_
    raise exception
  File "/home/airflow/.local/lib/python3.12/site-packages/sqlalchemy/pool/impl.py", line 143, in _do_get
    return self._create_connection()
           ^^^^^^^^^^^^^^^^^^^^^^^^^
  File "/home/airflow/.local/lib/python3.12/site-packages/sqlalchemy/pool/base.py", line 273, in _create_connection
    return _ConnectionRecord(self)
           ^^^^^^^^^^^^^^^^^^^^^^^
  File "/home/airflow/.local/lib/python3.12/site-packages/sqlalchemy/pool/base.py", line 388, in __init__
    self.__connect()
  File "/home/airflow/.local/lib/python3.12/site-packages/sqlalchemy/pool/base.py", line 690, in __connect
    with util.safe_reraise():
         ^^^^^^^^^^^^^^^^^^^
  File "/home/airflow/.local/lib/python3.12/site-packages/sqlalchemy/util/langhelpers.py", line 70, in __exit__
    compat.raise_(
  File "/home/airflow/.local/lib/python3.12/site-packages/sqlalchemy/util/compat.py", line 211, in raise_
    raise exception
  File "/home/airflow/.local/lib/python3.12/site-packages/sqlalchemy/pool/base.py", line 686, in __connect
    self.dbapi_connection = connection = pool._invoke_creator(self)
                                         ^^^^^^^^^^^^^^^^^^^^^^^^^^
  File "/home/airflow/.local/lib/python3.12/site-packages/sqlalchemy/engine/create.py", line 574, in connect
    return dialect.connect(*cargs, **cparams)
           ^^^^^^^^^^^^^^^^^^^^^^^^^^^^^^^^^^
  File "/home/airflow/.local/lib/python3.12/site-packages/sqlalchemy/engine/default.py", line 598, in connect
    return self.dbapi.connect(*cargs, **cparams)
           ^^^^^^^^^^^^^^^^^^^^^^^^^^^^^^^^^^^^^
  File "/home/airflow/.local/lib/python3.12/site-packages/psycopg2/__init__.py", line 122, in connect
    conn = _connect(dsn, connection_factory=connection_factory, **kwasync)
           ^^^^^^^^^^^^^^^^^^^^^^^^^^^^^^^^^^^^^^^^^^^^^^^^^^^^^^^^^^^^^^^
psycopg2.OperationalError: could not translate host name "postgres" to address: Temporary failure in name resolution


The above exception was the direct cause of the following exception:

Traceback (most recent call last):
  File "/home/airflow/.local/lib/python3.12/site-packages/airflow/dag_processing/processor.py", line 207, in _run_file_processor
    _handle_dag_file_processing()
  File "/home/airflow/.local/lib/python3.12/site-packages/airflow/dag_processing/processor.py", line 188, in _handle_dag_file_processing
    result: tuple[int, int, int] = dag_file_processor.process_file(
                                   ^^^^^^^^^^^^^^^^^^^^^^^^^^^^^^^^
  File "/home/airflow/.local/lib/python3.12/site-packages/airflow/utils/session.py", line 97, in wrapper
    return func(*args, session=session, **kwargs)
           ^^^^^^^^^^^^^^^^^^^^^^^^^^^^^^^^^^^^^^
  File "/home/airflow/.local/lib/python3.12/site-packages/airflow/dag_processing/processor.py", line 942, in process_file
    serialize_errors = DagFileProcessor.save_dag_to_db(
                       ^^^^^^^^^^^^^^^^^^^^^^^^^^^^^^^^
  File "/home/airflow/.local/lib/python3.12/site-packages/airflow/api_internal/internal_api_call.py", line 166, in wrapper
    return func(*args, **kwargs)
           ^^^^^^^^^^^^^^^^^^^^^
  File "/home/airflow/.local/lib/python3.12/site-packages/airflow/utils/session.py", line 97, in wrapper
    return func(*args, session=session, **kwargs)
           ^^^^^^^^^^^^^^^^^^^^^^^^^^^^^^^^^^^^^^
  File "/home/airflow/.local/lib/python3.12/site-packages/airflow/dag_processing/processor.py", line 982, in save_dag_to_db
    import_errors = DagBag._sync_to_db(dags=dags, processor_subdir=dag_directory, session=session)
                    ^^^^^^^^^^^^^^^^^^^^^^^^^^^^^^^^^^^^^^^^^^^^^^^^^^^^^^^^^^^^^^^^^^^^^^^^^^^^^^
  File "/home/airflow/.local/lib/python3.12/site-packages/airflow/utils/session.py", line 94, in wrapper
    return func(*args, **kwargs)
           ^^^^^^^^^^^^^^^^^^^^^
  File "/home/airflow/.local/lib/python3.12/site-packages/airflow/models/dagbag.py", line 708, in _sync_to_db
    for attempt in run_with_db_retries(logger=log):
                   ^^^^^^^^^^^^^^^^^^^^^^^^^^^^^^^
  File "/home/airflow/.local/lib/python3.12/site-packages/tenacity/__init__.py", line 443, in __iter__
    do = self.iter(retry_state=retry_state)
         ^^^^^^^^^^^^^^^^^^^^^^^^^^^^^^^^^^
  File "/home/airflow/.local/lib/python3.12/site-packages/tenacity/__init__.py", line 376, in iter
    result = action(retry_state)
             ^^^^^^^^^^^^^^^^^^^
  File "/home/airflow/.local/lib/python3.12/site-packages/tenacity/__init__.py", line 418, in exc_check
    raise retry_exc.reraise()
          ^^^^^^^^^^^^^^^^^^^
  File "/home/airflow/.local/lib/python3.12/site-packages/tenacity/__init__.py", line 185, in reraise
    raise self.last_attempt.result()
          ^^^^^^^^^^^^^^^^^^^^^^^^^^
  File "/usr/local/lib/python3.12/concurrent/futures/_base.py", line 449, in result
    return self.__get_result()
           ^^^^^^^^^^^^^^^^^^^
  File "/usr/local/lib/python3.12/concurrent/futures/_base.py", line 401, in __get_result
    raise self._exception
  File "/home/airflow/.local/lib/python3.12/site-packages/airflow/models/dagbag.py", line 721, in _sync_to_db
    _serialize_dag_capturing_errors(dag, session, processor_subdir)
  File "/home/airflow/.local/lib/python3.12/site-packages/airflow/models/dagbag.py", line 686, in _serialize_dag_capturing_errors
    dag_was_updated = SerializedDagModel.write_dag(
                      ^^^^^^^^^^^^^^^^^^^^^^^^^^^^^
  File "/home/airflow/.local/lib/python3.12/site-packages/airflow/utils/session.py", line 94, in wrapper
    return func(*args, **kwargs)
           ^^^^^^^^^^^^^^^^^^^^^
  File "/home/airflow/.local/lib/python3.12/site-packages/airflow/models/serialized_dag.py", line 160, in write_dag
    if session.scalar(
       ^^^^^^^^^^^^^^^
  File "/home/airflow/.local/lib/python3.12/site-packages/sqlalchemy/orm/session.py", line 1747, in scalar
    return self.execute(
           ^^^^^^^^^^^^^
  File "/home/airflow/.local/lib/python3.12/site-packages/sqlalchemy/orm/session.py", line 1716, in execute
    conn = self._connection_for_bind(bind)
           ^^^^^^^^^^^^^^^^^^^^^^^^^^^^^^^
  File "/home/airflow/.local/lib/python3.12/site-packages/sqlalchemy/orm/session.py", line 1555, in _connection_for_bind
    return self._transaction._connection_for_bind(
           ^^^^^^^^^^^^^^^^^^^^^^^^^^^^^^^^^^^^^^^
  File "/home/airflow/.local/lib/python3.12/site-packages/sqlalchemy/orm/session.py", line 750, in _connection_for_bind
    conn = bind.connect()
           ^^^^^^^^^^^^^^
  File "/home/airflow/.local/lib/python3.12/site-packages/sqlalchemy/future/engine.py", line 412, in connect
    return super(Engine, self).connect()
           ^^^^^^^^^^^^^^^^^^^^^^^^^^^^^
  File "/home/airflow/.local/lib/python3.12/site-packages/sqlalchemy/engine/base.py", line 3325, in connect
    return self._connection_cls(self, close_with_result=close_with_result)
           ^^^^^^^^^^^^^^^^^^^^^^^^^^^^^^^^^^^^^^^^^^^^^^^^^^^^^^^^^^^^^^^
  File "/home/airflow/.local/lib/python3.12/site-packages/sqlalchemy/engine/base.py", line 96, in __init__
    else engine.raw_connection()
         ^^^^^^^^^^^^^^^^^^^^^^^
  File "/home/airflow/.local/lib/python3.12/site-packages/sqlalchemy/engine/base.py", line 3404, in raw_connection
    return self._wrap_pool_connect(self.pool.connect, _connection)
           ^^^^^^^^^^^^^^^^^^^^^^^^^^^^^^^^^^^^^^^^^^^^^^^^^^^^^^^
  File "/home/airflow/.local/lib/python3.12/site-packages/sqlalchemy/engine/base.py", line 3374, in _wrap_pool_connect
    Connection._handle_dbapi_exception_noconnection(
  File "/home/airflow/.local/lib/python3.12/site-packages/sqlalchemy/engine/base.py", line 2208, in _handle_dbapi_exception_noconnection
    util.raise_(
  File "/home/airflow/.local/lib/python3.12/site-packages/sqlalchemy/util/compat.py", line 211, in raise_
    raise exception
  File "/home/airflow/.local/lib/python3.12/site-packages/sqlalchemy/engine/base.py", line 3371, in _wrap_pool_connect
    return fn()
           ^^^^
  File "/home/airflow/.local/lib/python3.12/site-packages/sqlalchemy/pool/base.py", line 327, in connect
    return _ConnectionFairy._checkout(self)
           ^^^^^^^^^^^^^^^^^^^^^^^^^^^^^^^^
  File "/home/airflow/.local/lib/python3.12/site-packages/sqlalchemy/pool/base.py", line 894, in _checkout
    fairy = _ConnectionRecord.checkout(pool)
            ^^^^^^^^^^^^^^^^^^^^^^^^^^^^^^^^
  File "/home/airflow/.local/lib/python3.12/site-packages/sqlalchemy/pool/base.py", line 493, in checkout
    rec = pool._do_get()
          ^^^^^^^^^^^^^^
  File "/home/airflow/.local/lib/python3.12/site-packages/sqlalchemy/pool/impl.py", line 145, in _do_get
    with util.safe_reraise():
         ^^^^^^^^^^^^^^^^^^^
  File "/home/airflow/.local/lib/python3.12/site-packages/sqlalchemy/util/langhelpers.py", line 70, in __exit__
    compat.raise_(
  File "/home/airflow/.local/lib/python3.12/site-packages/sqlalchemy/util/compat.py", line 211, in raise_
    raise exception
  File "/home/airflow/.local/lib/python3.12/site-packages/sqlalchemy/pool/impl.py", line 143, in _do_get
    return self._create_connection()
           ^^^^^^^^^^^^^^^^^^^^^^^^^
  File "/home/airflow/.local/lib/python3.12/site-packages/sqlalchemy/pool/base.py", line 273, in _create_connection
    return _ConnectionRecord(self)
           ^^^^^^^^^^^^^^^^^^^^^^^
  File "/home/airflow/.local/lib/python3.12/site-packages/sqlalchemy/pool/base.py", line 388, in __init__
    self.__connect()
  File "/home/airflow/.local/lib/python3.12/site-packages/sqlalchemy/pool/base.py", line 690, in __connect
    with util.safe_reraise():
         ^^^^^^^^^^^^^^^^^^^
  File "/home/airflow/.local/lib/python3.12/site-packages/sqlalchemy/util/langhelpers.py", line 70, in __exit__
    compat.raise_(
  File "/home/airflow/.local/lib/python3.12/site-packages/sqlalchemy/util/compat.py", line 211, in raise_
    raise exception
  File "/home/airflow/.local/lib/python3.12/site-packages/sqlalchemy/pool/base.py", line 686, in __connect
    self.dbapi_connection = connection = pool._invoke_creator(self)
                                         ^^^^^^^^^^^^^^^^^^^^^^^^^^
  File "/home/airflow/.local/lib/python3.12/site-packages/sqlalchemy/engine/create.py", line 574, in connect
    return dialect.connect(*cargs, **cparams)
           ^^^^^^^^^^^^^^^^^^^^^^^^^^^^^^^^^^
  File "/home/airflow/.local/lib/python3.12/site-packages/sqlalchemy/engine/default.py", line 598, in connect
    return self.dbapi.connect(*cargs, **cparams)
           ^^^^^^^^^^^^^^^^^^^^^^^^^^^^^^^^^^^^^
  File "/home/airflow/.local/lib/python3.12/site-packages/psycopg2/__init__.py", line 122, in connect
    conn = _connect(dsn, connection_factory=connection_factory, **kwasync)
           ^^^^^^^^^^^^^^^^^^^^^^^^^^^^^^^^^^^^^^^^^^^^^^^^^^^^^^^^^^^^^^^
sqlalchemy.exc.OperationalError: (psycopg2.OperationalError) could not translate host name "postgres" to address: Temporary failure in name resolution

(Background on this error at: https://sqlalche.me/e/14/e3q8)
[2025-01-16T20:05:47.187+0000] {processor.py:186} INFO - Started process (PID=76) to work on /opt/airflow/dags/test.py
[2025-01-16T20:05:47.190+0000] {processor.py:914} INFO - Processing file /opt/airflow/dags/test.py for tasks to queue
[2025-01-16T20:05:47.195+0000] {logging_mixin.py:190} INFO - [2025-01-16T20:05:47.194+0000] {dagbag.py:588} INFO - Filling up the DagBag from /opt/airflow/dags/test.py
[2025-01-16T20:05:47.522+0000] {logging_mixin.py:190} INFO - [2025-01-16T20:05:47.519+0000] {templater.py:94} ERROR - Failed to resolve template field '_sql'
Traceback (most recent call last):
  File "/home/airflow/.local/lib/python3.12/site-packages/airflow/template/templater.py", line 92, in resolve_template_files
    setattr(self, field, env.loader.get_source(env, content)[0])  # type: ignore
                         ^^^^^^^^^^^^^^^^^^^^^^^^^^^^^^^^^^^
  File "/home/airflow/.local/lib/python3.12/site-packages/jinja2/loaders.py", line 207, in get_source
    raise TemplateNotFound(template)
jinja2.exceptions.TemplateNotFound: test.sql
[2025-01-16T20:05:47.526+0000] {processor.py:925} INFO - DAG(s) 'test' retrieved from /opt/airflow/dags/test.py
[2025-01-16T20:05:47.873+0000] {logging_mixin.py:190} INFO - [2025-01-16T20:05:47.873+0000] {dag.py:3239} INFO - Sync 1 DAGs
[2025-01-16T20:05:47.889+0000] {logging_mixin.py:190} INFO - [2025-01-16T20:05:47.888+0000] {dag.py:4180} INFO - Setting next_dagrun for test to None, run_after=None
[2025-01-16T20:05:47.974+0000] {processor.py:208} INFO - Processing /opt/airflow/dags/test.py took 0.797 seconds
[2025-01-16T20:06:18.319+0000] {processor.py:186} INFO - Started process (PID=93) to work on /opt/airflow/dags/test.py
[2025-01-16T20:06:18.321+0000] {processor.py:914} INFO - Processing file /opt/airflow/dags/test.py for tasks to queue
[2025-01-16T20:06:18.325+0000] {logging_mixin.py:190} INFO - [2025-01-16T20:06:18.325+0000] {dagbag.py:588} INFO - Filling up the DagBag from /opt/airflow/dags/test.py
[2025-01-16T20:06:18.497+0000] {logging_mixin.py:190} INFO - [2025-01-16T20:06:18.496+0000] {templater.py:94} ERROR - Failed to resolve template field '_sql'
Traceback (most recent call last):
  File "/home/airflow/.local/lib/python3.12/site-packages/airflow/template/templater.py", line 92, in resolve_template_files
    setattr(self, field, env.loader.get_source(env, content)[0])  # type: ignore
                         ^^^^^^^^^^^^^^^^^^^^^^^^^^^^^^^^^^^
  File "/home/airflow/.local/lib/python3.12/site-packages/jinja2/loaders.py", line 207, in get_source
    raise TemplateNotFound(template)
jinja2.exceptions.TemplateNotFound: test.sql
[2025-01-16T20:06:18.499+0000] {processor.py:925} INFO - DAG(s) 'test' retrieved from /opt/airflow/dags/test.py
[2025-01-16T20:06:18.520+0000] {logging_mixin.py:190} INFO - [2025-01-16T20:06:18.520+0000] {dag.py:3239} INFO - Sync 1 DAGs
[2025-01-16T20:06:18.532+0000] {logging_mixin.py:190} INFO - [2025-01-16T20:06:18.532+0000] {dag.py:4180} INFO - Setting next_dagrun for test to None, run_after=None
[2025-01-16T20:06:18.555+0000] {processor.py:208} INFO - Processing /opt/airflow/dags/test.py took 0.240 seconds
[2025-01-16T20:06:49.059+0000] {processor.py:186} INFO - Started process (PID=103) to work on /opt/airflow/dags/test.py
[2025-01-16T20:06:49.060+0000] {processor.py:914} INFO - Processing file /opt/airflow/dags/test.py for tasks to queue
[2025-01-16T20:06:49.063+0000] {logging_mixin.py:190} INFO - [2025-01-16T20:06:49.063+0000] {dagbag.py:588} INFO - Filling up the DagBag from /opt/airflow/dags/test.py
[2025-01-16T20:06:49.195+0000] {logging_mixin.py:190} INFO - [2025-01-16T20:06:49.194+0000] {templater.py:94} ERROR - Failed to resolve template field '_sql'
Traceback (most recent call last):
  File "/home/airflow/.local/lib/python3.12/site-packages/airflow/template/templater.py", line 92, in resolve_template_files
    setattr(self, field, env.loader.get_source(env, content)[0])  # type: ignore
                         ^^^^^^^^^^^^^^^^^^^^^^^^^^^^^^^^^^^
  File "/home/airflow/.local/lib/python3.12/site-packages/jinja2/loaders.py", line 207, in get_source
    raise TemplateNotFound(template)
jinja2.exceptions.TemplateNotFound: test.sql
[2025-01-16T20:06:49.197+0000] {processor.py:925} INFO - DAG(s) 'test' retrieved from /opt/airflow/dags/test.py
[2025-01-16T20:06:49.220+0000] {logging_mixin.py:190} INFO - [2025-01-16T20:06:49.220+0000] {dag.py:3239} INFO - Sync 1 DAGs
[2025-01-16T20:06:49.358+0000] {logging_mixin.py:190} INFO - [2025-01-16T20:06:49.358+0000] {dag.py:4180} INFO - Setting next_dagrun for test to None, run_after=None
[2025-01-16T20:06:49.378+0000] {processor.py:208} INFO - Processing /opt/airflow/dags/test.py took 0.324 seconds
[2025-01-16T20:07:19.438+0000] {processor.py:186} INFO - Started process (PID=113) to work on /opt/airflow/dags/test.py
[2025-01-16T20:07:19.439+0000] {processor.py:914} INFO - Processing file /opt/airflow/dags/test.py for tasks to queue
[2025-01-16T20:07:19.441+0000] {logging_mixin.py:190} INFO - [2025-01-16T20:07:19.440+0000] {dagbag.py:588} INFO - Filling up the DagBag from /opt/airflow/dags/test.py
[2025-01-16T20:07:19.570+0000] {logging_mixin.py:190} INFO - [2025-01-16T20:07:19.570+0000] {templater.py:94} ERROR - Failed to resolve template field '_sql'
Traceback (most recent call last):
  File "/home/airflow/.local/lib/python3.12/site-packages/airflow/template/templater.py", line 92, in resolve_template_files
    setattr(self, field, env.loader.get_source(env, content)[0])  # type: ignore
                         ^^^^^^^^^^^^^^^^^^^^^^^^^^^^^^^^^^^
  File "/home/airflow/.local/lib/python3.12/site-packages/jinja2/loaders.py", line 207, in get_source
    raise TemplateNotFound(template)
jinja2.exceptions.TemplateNotFound: test.sql
[2025-01-16T20:07:19.572+0000] {processor.py:925} INFO - DAG(s) 'test' retrieved from /opt/airflow/dags/test.py
[2025-01-16T20:07:19.592+0000] {logging_mixin.py:190} INFO - [2025-01-16T20:07:19.592+0000] {dag.py:3239} INFO - Sync 1 DAGs
[2025-01-16T20:07:19.704+0000] {logging_mixin.py:190} INFO - [2025-01-16T20:07:19.704+0000] {dag.py:4180} INFO - Setting next_dagrun for test to None, run_after=None
[2025-01-16T20:07:19.726+0000] {processor.py:208} INFO - Processing /opt/airflow/dags/test.py took 0.292 seconds
[2025-01-16T20:07:49.867+0000] {processor.py:186} INFO - Started process (PID=124) to work on /opt/airflow/dags/test.py
[2025-01-16T20:07:49.868+0000] {processor.py:914} INFO - Processing file /opt/airflow/dags/test.py for tasks to queue
[2025-01-16T20:07:49.870+0000] {logging_mixin.py:190} INFO - [2025-01-16T20:07:49.870+0000] {dagbag.py:588} INFO - Filling up the DagBag from /opt/airflow/dags/test.py
[2025-01-16T20:07:49.995+0000] {logging_mixin.py:190} INFO - [2025-01-16T20:07:49.995+0000] {templater.py:94} ERROR - Failed to resolve template field '_sql'
Traceback (most recent call last):
  File "/home/airflow/.local/lib/python3.12/site-packages/airflow/template/templater.py", line 92, in resolve_template_files
    setattr(self, field, env.loader.get_source(env, content)[0])  # type: ignore
                         ^^^^^^^^^^^^^^^^^^^^^^^^^^^^^^^^^^^
  File "/home/airflow/.local/lib/python3.12/site-packages/jinja2/loaders.py", line 207, in get_source
    raise TemplateNotFound(template)
jinja2.exceptions.TemplateNotFound: test.sql
[2025-01-16T20:07:49.997+0000] {processor.py:925} INFO - DAG(s) 'test' retrieved from /opt/airflow/dags/test.py
[2025-01-16T20:07:50.128+0000] {logging_mixin.py:190} INFO - [2025-01-16T20:07:50.128+0000] {dag.py:3239} INFO - Sync 1 DAGs
[2025-01-16T20:07:50.141+0000] {logging_mixin.py:190} INFO - [2025-01-16T20:07:50.141+0000] {dag.py:4180} INFO - Setting next_dagrun for test to None, run_after=None
[2025-01-16T20:07:50.171+0000] {processor.py:208} INFO - Processing /opt/airflow/dags/test.py took 0.308 seconds
[2025-01-16T20:08:20.221+0000] {processor.py:186} INFO - Started process (PID=135) to work on /opt/airflow/dags/test.py
[2025-01-16T20:08:20.269+0000] {processor.py:914} INFO - Processing file /opt/airflow/dags/test.py for tasks to queue
[2025-01-16T20:08:20.273+0000] {logging_mixin.py:190} INFO - [2025-01-16T20:08:20.273+0000] {dagbag.py:588} INFO - Filling up the DagBag from /opt/airflow/dags/test.py
[2025-01-16T20:08:20.535+0000] {logging_mixin.py:190} INFO - [2025-01-16T20:08:20.535+0000] {templater.py:94} ERROR - Failed to resolve template field '_sql'
Traceback (most recent call last):
  File "/home/airflow/.local/lib/python3.12/site-packages/airflow/template/templater.py", line 92, in resolve_template_files
    setattr(self, field, env.loader.get_source(env, content)[0])  # type: ignore
                         ^^^^^^^^^^^^^^^^^^^^^^^^^^^^^^^^^^^
  File "/home/airflow/.local/lib/python3.12/site-packages/jinja2/loaders.py", line 207, in get_source
    raise TemplateNotFound(template)
jinja2.exceptions.TemplateNotFound: test.sql
[2025-01-16T20:08:20.537+0000] {processor.py:925} INFO - DAG(s) 'test' retrieved from /opt/airflow/dags/test.py
[2025-01-16T20:08:20.569+0000] {logging_mixin.py:190} INFO - [2025-01-16T20:08:20.569+0000] {dag.py:3239} INFO - Sync 1 DAGs
[2025-01-16T20:08:20.580+0000] {logging_mixin.py:190} INFO - [2025-01-16T20:08:20.579+0000] {dag.py:4180} INFO - Setting next_dagrun for test to None, run_after=None
[2025-01-16T20:08:20.598+0000] {processor.py:208} INFO - Processing /opt/airflow/dags/test.py took 0.382 seconds
[2025-01-16T20:08:50.956+0000] {processor.py:186} INFO - Started process (PID=146) to work on /opt/airflow/dags/test.py
[2025-01-16T20:08:50.957+0000] {processor.py:914} INFO - Processing file /opt/airflow/dags/test.py for tasks to queue
[2025-01-16T20:08:50.959+0000] {logging_mixin.py:190} INFO - [2025-01-16T20:08:50.959+0000] {dagbag.py:588} INFO - Filling up the DagBag from /opt/airflow/dags/test.py
[2025-01-16T20:08:51.339+0000] {logging_mixin.py:190} INFO - [2025-01-16T20:08:51.338+0000] {templater.py:94} ERROR - Failed to resolve template field '_sql'
Traceback (most recent call last):
  File "/home/airflow/.local/lib/python3.12/site-packages/airflow/template/templater.py", line 92, in resolve_template_files
    setattr(self, field, env.loader.get_source(env, content)[0])  # type: ignore
                         ^^^^^^^^^^^^^^^^^^^^^^^^^^^^^^^^^^^
  File "/home/airflow/.local/lib/python3.12/site-packages/jinja2/loaders.py", line 207, in get_source
    raise TemplateNotFound(template)
jinja2.exceptions.TemplateNotFound: test.sql
[2025-01-16T20:08:51.341+0000] {processor.py:925} INFO - DAG(s) 'test' retrieved from /opt/airflow/dags/test.py
[2025-01-16T20:08:51.359+0000] {logging_mixin.py:190} INFO - [2025-01-16T20:08:51.359+0000] {dag.py:3239} INFO - Sync 1 DAGs
[2025-01-16T20:08:51.370+0000] {logging_mixin.py:190} INFO - [2025-01-16T20:08:51.370+0000] {dag.py:4180} INFO - Setting next_dagrun for test to None, run_after=None
[2025-01-16T20:08:51.390+0000] {processor.py:208} INFO - Processing /opt/airflow/dags/test.py took 0.439 seconds
[2025-01-16T20:09:21.861+0000] {processor.py:186} INFO - Started process (PID=157) to work on /opt/airflow/dags/test.py
[2025-01-16T20:09:21.863+0000] {processor.py:914} INFO - Processing file /opt/airflow/dags/test.py for tasks to queue
[2025-01-16T20:09:21.865+0000] {logging_mixin.py:190} INFO - [2025-01-16T20:09:21.865+0000] {dagbag.py:588} INFO - Filling up the DagBag from /opt/airflow/dags/test.py
[2025-01-16T20:09:22.035+0000] {logging_mixin.py:190} INFO - [2025-01-16T20:09:22.035+0000] {templater.py:94} ERROR - Failed to resolve template field '_sql'
Traceback (most recent call last):
  File "/home/airflow/.local/lib/python3.12/site-packages/airflow/template/templater.py", line 92, in resolve_template_files
    setattr(self, field, env.loader.get_source(env, content)[0])  # type: ignore
                         ^^^^^^^^^^^^^^^^^^^^^^^^^^^^^^^^^^^
  File "/home/airflow/.local/lib/python3.12/site-packages/jinja2/loaders.py", line 207, in get_source
    raise TemplateNotFound(template)
jinja2.exceptions.TemplateNotFound: test.sql
[2025-01-16T20:09:22.037+0000] {processor.py:925} INFO - DAG(s) 'test' retrieved from /opt/airflow/dags/test.py
[2025-01-16T20:09:22.056+0000] {logging_mixin.py:190} INFO - [2025-01-16T20:09:22.056+0000] {dag.py:3239} INFO - Sync 1 DAGs
[2025-01-16T20:09:22.067+0000] {logging_mixin.py:190} INFO - [2025-01-16T20:09:22.067+0000] {dag.py:4180} INFO - Setting next_dagrun for test to None, run_after=None
[2025-01-16T20:09:22.093+0000] {processor.py:208} INFO - Processing /opt/airflow/dags/test.py took 0.237 seconds
[2025-01-16T20:09:52.385+0000] {processor.py:186} INFO - Started process (PID=168) to work on /opt/airflow/dags/test.py
[2025-01-16T20:09:52.386+0000] {processor.py:914} INFO - Processing file /opt/airflow/dags/test.py for tasks to queue
[2025-01-16T20:09:52.389+0000] {logging_mixin.py:190} INFO - [2025-01-16T20:09:52.389+0000] {dagbag.py:588} INFO - Filling up the DagBag from /opt/airflow/dags/test.py
[2025-01-16T20:09:52.554+0000] {logging_mixin.py:190} INFO - [2025-01-16T20:09:52.553+0000] {templater.py:94} ERROR - Failed to resolve template field '_sql'
Traceback (most recent call last):
  File "/home/airflow/.local/lib/python3.12/site-packages/airflow/template/templater.py", line 92, in resolve_template_files
    setattr(self, field, env.loader.get_source(env, content)[0])  # type: ignore
                         ^^^^^^^^^^^^^^^^^^^^^^^^^^^^^^^^^^^
  File "/home/airflow/.local/lib/python3.12/site-packages/jinja2/loaders.py", line 207, in get_source
    raise TemplateNotFound(template)
jinja2.exceptions.TemplateNotFound: test.sql
[2025-01-16T20:09:52.556+0000] {processor.py:925} INFO - DAG(s) 'test' retrieved from /opt/airflow/dags/test.py
[2025-01-16T20:09:52.577+0000] {logging_mixin.py:190} INFO - [2025-01-16T20:09:52.577+0000] {dag.py:3239} INFO - Sync 1 DAGs
[2025-01-16T20:09:52.587+0000] {logging_mixin.py:190} INFO - [2025-01-16T20:09:52.587+0000] {dag.py:4180} INFO - Setting next_dagrun for test to None, run_after=None
[2025-01-16T20:09:52.625+0000] {processor.py:208} INFO - Processing /opt/airflow/dags/test.py took 0.245 seconds
[2025-01-16T20:10:23.266+0000] {processor.py:186} INFO - Started process (PID=179) to work on /opt/airflow/dags/test.py
[2025-01-16T20:10:23.267+0000] {processor.py:914} INFO - Processing file /opt/airflow/dags/test.py for tasks to queue
[2025-01-16T20:10:23.269+0000] {logging_mixin.py:190} INFO - [2025-01-16T20:10:23.269+0000] {dagbag.py:588} INFO - Filling up the DagBag from /opt/airflow/dags/test.py
[2025-01-16T20:10:23.414+0000] {logging_mixin.py:190} INFO - [2025-01-16T20:10:23.413+0000] {templater.py:94} ERROR - Failed to resolve template field '_sql'
Traceback (most recent call last):
  File "/home/airflow/.local/lib/python3.12/site-packages/airflow/template/templater.py", line 92, in resolve_template_files
    setattr(self, field, env.loader.get_source(env, content)[0])  # type: ignore
                         ^^^^^^^^^^^^^^^^^^^^^^^^^^^^^^^^^^^
  File "/home/airflow/.local/lib/python3.12/site-packages/jinja2/loaders.py", line 207, in get_source
    raise TemplateNotFound(template)
jinja2.exceptions.TemplateNotFound: test.sql
[2025-01-16T20:10:23.416+0000] {processor.py:925} INFO - DAG(s) 'test' retrieved from /opt/airflow/dags/test.py
[2025-01-16T20:10:23.438+0000] {logging_mixin.py:190} INFO - [2025-01-16T20:10:23.438+0000] {dag.py:3239} INFO - Sync 1 DAGs
[2025-01-16T20:10:23.450+0000] {logging_mixin.py:190} INFO - [2025-01-16T20:10:23.449+0000] {dag.py:4180} INFO - Setting next_dagrun for test to None, run_after=None
[2025-01-16T20:10:23.472+0000] {processor.py:208} INFO - Processing /opt/airflow/dags/test.py took 0.212 seconds
[2025-01-16T20:10:54.204+0000] {processor.py:186} INFO - Started process (PID=190) to work on /opt/airflow/dags/test.py
[2025-01-16T20:10:54.205+0000] {processor.py:914} INFO - Processing file /opt/airflow/dags/test.py for tasks to queue
[2025-01-16T20:10:54.206+0000] {logging_mixin.py:190} INFO - [2025-01-16T20:10:54.206+0000] {dagbag.py:588} INFO - Filling up the DagBag from /opt/airflow/dags/test.py
[2025-01-16T20:10:54.327+0000] {logging_mixin.py:190} INFO - [2025-01-16T20:10:54.326+0000] {templater.py:94} ERROR - Failed to resolve template field '_sql'
Traceback (most recent call last):
  File "/home/airflow/.local/lib/python3.12/site-packages/airflow/template/templater.py", line 92, in resolve_template_files
    setattr(self, field, env.loader.get_source(env, content)[0])  # type: ignore
                         ^^^^^^^^^^^^^^^^^^^^^^^^^^^^^^^^^^^
  File "/home/airflow/.local/lib/python3.12/site-packages/jinja2/loaders.py", line 207, in get_source
    raise TemplateNotFound(template)
jinja2.exceptions.TemplateNotFound: test.sql
[2025-01-16T20:10:54.329+0000] {processor.py:925} INFO - DAG(s) 'test' retrieved from /opt/airflow/dags/test.py
[2025-01-16T20:10:54.346+0000] {logging_mixin.py:190} INFO - [2025-01-16T20:10:54.346+0000] {dag.py:3239} INFO - Sync 1 DAGs
[2025-01-16T20:10:54.356+0000] {logging_mixin.py:190} INFO - [2025-01-16T20:10:54.355+0000] {dag.py:4180} INFO - Setting next_dagrun for test to None, run_after=None
[2025-01-16T20:10:54.384+0000] {processor.py:208} INFO - Processing /opt/airflow/dags/test.py took 0.185 seconds
[2025-01-16T20:11:25.062+0000] {processor.py:186} INFO - Started process (PID=201) to work on /opt/airflow/dags/test.py
[2025-01-16T20:11:25.063+0000] {processor.py:914} INFO - Processing file /opt/airflow/dags/test.py for tasks to queue
[2025-01-16T20:11:25.065+0000] {logging_mixin.py:190} INFO - [2025-01-16T20:11:25.064+0000] {dagbag.py:588} INFO - Filling up the DagBag from /opt/airflow/dags/test.py
[2025-01-16T20:11:25.203+0000] {logging_mixin.py:190} INFO - [2025-01-16T20:11:25.202+0000] {templater.py:94} ERROR - Failed to resolve template field '_sql'
Traceback (most recent call last):
  File "/home/airflow/.local/lib/python3.12/site-packages/airflow/template/templater.py", line 92, in resolve_template_files
    setattr(self, field, env.loader.get_source(env, content)[0])  # type: ignore
                         ^^^^^^^^^^^^^^^^^^^^^^^^^^^^^^^^^^^
  File "/home/airflow/.local/lib/python3.12/site-packages/jinja2/loaders.py", line 207, in get_source
    raise TemplateNotFound(template)
jinja2.exceptions.TemplateNotFound: test.sql
[2025-01-16T20:11:25.205+0000] {processor.py:925} INFO - DAG(s) 'test' retrieved from /opt/airflow/dags/test.py
[2025-01-16T20:11:25.225+0000] {logging_mixin.py:190} INFO - [2025-01-16T20:11:25.225+0000] {dag.py:3239} INFO - Sync 1 DAGs
[2025-01-16T20:11:25.235+0000] {logging_mixin.py:190} INFO - [2025-01-16T20:11:25.235+0000] {dag.py:4180} INFO - Setting next_dagrun for test to None, run_after=None
[2025-01-16T20:11:25.262+0000] {processor.py:208} INFO - Processing /opt/airflow/dags/test.py took 0.207 seconds
[2025-01-16T20:11:55.398+0000] {processor.py:186} INFO - Started process (PID=212) to work on /opt/airflow/dags/test.py
[2025-01-16T20:11:55.399+0000] {processor.py:914} INFO - Processing file /opt/airflow/dags/test.py for tasks to queue
[2025-01-16T20:11:55.401+0000] {logging_mixin.py:190} INFO - [2025-01-16T20:11:55.401+0000] {dagbag.py:588} INFO - Filling up the DagBag from /opt/airflow/dags/test.py
[2025-01-16T20:11:55.549+0000] {logging_mixin.py:190} INFO - [2025-01-16T20:11:55.548+0000] {templater.py:94} ERROR - Failed to resolve template field '_sql'
Traceback (most recent call last):
  File "/home/airflow/.local/lib/python3.12/site-packages/airflow/template/templater.py", line 92, in resolve_template_files
    setattr(self, field, env.loader.get_source(env, content)[0])  # type: ignore
                         ^^^^^^^^^^^^^^^^^^^^^^^^^^^^^^^^^^^
  File "/home/airflow/.local/lib/python3.12/site-packages/jinja2/loaders.py", line 207, in get_source
    raise TemplateNotFound(template)
jinja2.exceptions.TemplateNotFound: test.sql
[2025-01-16T20:11:55.551+0000] {processor.py:925} INFO - DAG(s) 'test' retrieved from /opt/airflow/dags/test.py
[2025-01-16T20:11:55.572+0000] {logging_mixin.py:190} INFO - [2025-01-16T20:11:55.572+0000] {dag.py:3239} INFO - Sync 1 DAGs
[2025-01-16T20:11:55.583+0000] {logging_mixin.py:190} INFO - [2025-01-16T20:11:55.583+0000] {dag.py:4180} INFO - Setting next_dagrun for test to None, run_after=None
[2025-01-16T20:11:55.604+0000] {processor.py:208} INFO - Processing /opt/airflow/dags/test.py took 0.211 seconds
[2025-01-16T20:12:26.160+0000] {processor.py:186} INFO - Started process (PID=223) to work on /opt/airflow/dags/test.py
[2025-01-16T20:12:26.160+0000] {processor.py:914} INFO - Processing file /opt/airflow/dags/test.py for tasks to queue
[2025-01-16T20:12:26.162+0000] {logging_mixin.py:190} INFO - [2025-01-16T20:12:26.162+0000] {dagbag.py:588} INFO - Filling up the DagBag from /opt/airflow/dags/test.py
[2025-01-16T20:12:26.291+0000] {logging_mixin.py:190} INFO - [2025-01-16T20:12:26.290+0000] {templater.py:94} ERROR - Failed to resolve template field '_sql'
Traceback (most recent call last):
  File "/home/airflow/.local/lib/python3.12/site-packages/airflow/template/templater.py", line 92, in resolve_template_files
    setattr(self, field, env.loader.get_source(env, content)[0])  # type: ignore
                         ^^^^^^^^^^^^^^^^^^^^^^^^^^^^^^^^^^^
  File "/home/airflow/.local/lib/python3.12/site-packages/jinja2/loaders.py", line 207, in get_source
    raise TemplateNotFound(template)
jinja2.exceptions.TemplateNotFound: test.sql
[2025-01-16T20:12:26.293+0000] {processor.py:925} INFO - DAG(s) 'test' retrieved from /opt/airflow/dags/test.py
[2025-01-16T20:12:26.313+0000] {logging_mixin.py:190} INFO - [2025-01-16T20:12:26.312+0000] {dag.py:3239} INFO - Sync 1 DAGs
[2025-01-16T20:12:26.322+0000] {logging_mixin.py:190} INFO - [2025-01-16T20:12:26.322+0000] {dag.py:4180} INFO - Setting next_dagrun for test to None, run_after=None
[2025-01-16T20:12:26.342+0000] {processor.py:208} INFO - Processing /opt/airflow/dags/test.py took 0.187 seconds
[2025-01-16T20:12:56.514+0000] {processor.py:186} INFO - Started process (PID=234) to work on /opt/airflow/dags/test.py
[2025-01-16T20:12:56.516+0000] {processor.py:914} INFO - Processing file /opt/airflow/dags/test.py for tasks to queue
[2025-01-16T20:12:56.518+0000] {logging_mixin.py:190} INFO - [2025-01-16T20:12:56.518+0000] {dagbag.py:588} INFO - Filling up the DagBag from /opt/airflow/dags/test.py
[2025-01-16T20:12:56.707+0000] {logging_mixin.py:190} INFO - [2025-01-16T20:12:56.706+0000] {templater.py:94} ERROR - Failed to resolve template field '_sql'
Traceback (most recent call last):
  File "/home/airflow/.local/lib/python3.12/site-packages/airflow/template/templater.py", line 92, in resolve_template_files
    setattr(self, field, env.loader.get_source(env, content)[0])  # type: ignore
                         ^^^^^^^^^^^^^^^^^^^^^^^^^^^^^^^^^^^
  File "/home/airflow/.local/lib/python3.12/site-packages/jinja2/loaders.py", line 207, in get_source
    raise TemplateNotFound(template)
jinja2.exceptions.TemplateNotFound: test.sql
[2025-01-16T20:12:56.709+0000] {processor.py:925} INFO - DAG(s) 'test' retrieved from /opt/airflow/dags/test.py
[2025-01-16T20:12:56.727+0000] {logging_mixin.py:190} INFO - [2025-01-16T20:12:56.727+0000] {dag.py:3239} INFO - Sync 1 DAGs
[2025-01-16T20:12:56.737+0000] {logging_mixin.py:190} INFO - [2025-01-16T20:12:56.737+0000] {dag.py:4180} INFO - Setting next_dagrun for test to None, run_after=None
[2025-01-16T20:12:56.755+0000] {processor.py:208} INFO - Processing /opt/airflow/dags/test.py took 0.245 seconds
[2025-01-16T20:13:26.884+0000] {processor.py:186} INFO - Started process (PID=244) to work on /opt/airflow/dags/test.py
[2025-01-16T20:13:26.885+0000] {processor.py:914} INFO - Processing file /opt/airflow/dags/test.py for tasks to queue
[2025-01-16T20:13:26.887+0000] {logging_mixin.py:190} INFO - [2025-01-16T20:13:26.886+0000] {dagbag.py:588} INFO - Filling up the DagBag from /opt/airflow/dags/test.py
[2025-01-16T20:13:27.017+0000] {logging_mixin.py:190} INFO - [2025-01-16T20:13:27.016+0000] {templater.py:94} ERROR - Failed to resolve template field '_sql'
Traceback (most recent call last):
  File "/home/airflow/.local/lib/python3.12/site-packages/airflow/template/templater.py", line 92, in resolve_template_files
    setattr(self, field, env.loader.get_source(env, content)[0])  # type: ignore
                         ^^^^^^^^^^^^^^^^^^^^^^^^^^^^^^^^^^^
  File "/home/airflow/.local/lib/python3.12/site-packages/jinja2/loaders.py", line 207, in get_source
    raise TemplateNotFound(template)
jinja2.exceptions.TemplateNotFound: test.sql
[2025-01-16T20:13:27.019+0000] {processor.py:925} INFO - DAG(s) 'test' retrieved from /opt/airflow/dags/test.py
[2025-01-16T20:13:27.036+0000] {logging_mixin.py:190} INFO - [2025-01-16T20:13:27.036+0000] {dag.py:3239} INFO - Sync 1 DAGs
[2025-01-16T20:13:27.047+0000] {logging_mixin.py:190} INFO - [2025-01-16T20:13:27.047+0000] {dag.py:4180} INFO - Setting next_dagrun for test to None, run_after=None
[2025-01-16T20:13:27.078+0000] {processor.py:208} INFO - Processing /opt/airflow/dags/test.py took 0.197 seconds
[2025-01-16T20:13:57.653+0000] {processor.py:186} INFO - Started process (PID=255) to work on /opt/airflow/dags/test.py
[2025-01-16T20:13:57.654+0000] {processor.py:914} INFO - Processing file /opt/airflow/dags/test.py for tasks to queue
[2025-01-16T20:13:57.657+0000] {logging_mixin.py:190} INFO - [2025-01-16T20:13:57.657+0000] {dagbag.py:588} INFO - Filling up the DagBag from /opt/airflow/dags/test.py
[2025-01-16T20:13:57.787+0000] {logging_mixin.py:190} INFO - [2025-01-16T20:13:57.786+0000] {templater.py:94} ERROR - Failed to resolve template field '_sql'
Traceback (most recent call last):
  File "/home/airflow/.local/lib/python3.12/site-packages/airflow/template/templater.py", line 92, in resolve_template_files
    setattr(self, field, env.loader.get_source(env, content)[0])  # type: ignore
                         ^^^^^^^^^^^^^^^^^^^^^^^^^^^^^^^^^^^
  File "/home/airflow/.local/lib/python3.12/site-packages/jinja2/loaders.py", line 207, in get_source
    raise TemplateNotFound(template)
jinja2.exceptions.TemplateNotFound: test.sql
[2025-01-16T20:13:57.788+0000] {processor.py:925} INFO - DAG(s) 'test' retrieved from /opt/airflow/dags/test.py
[2025-01-16T20:13:57.807+0000] {logging_mixin.py:190} INFO - [2025-01-16T20:13:57.807+0000] {dag.py:3239} INFO - Sync 1 DAGs
[2025-01-16T20:13:57.818+0000] {logging_mixin.py:190} INFO - [2025-01-16T20:13:57.818+0000] {dag.py:4180} INFO - Setting next_dagrun for test to None, run_after=None
[2025-01-16T20:13:57.852+0000] {processor.py:208} INFO - Processing /opt/airflow/dags/test.py took 0.202 seconds
[2025-01-16T20:14:28.417+0000] {processor.py:186} INFO - Started process (PID=266) to work on /opt/airflow/dags/test.py
[2025-01-16T20:14:28.417+0000] {processor.py:914} INFO - Processing file /opt/airflow/dags/test.py for tasks to queue
[2025-01-16T20:14:28.419+0000] {logging_mixin.py:190} INFO - [2025-01-16T20:14:28.419+0000] {dagbag.py:588} INFO - Filling up the DagBag from /opt/airflow/dags/test.py
[2025-01-16T20:14:28.562+0000] {logging_mixin.py:190} INFO - [2025-01-16T20:14:28.561+0000] {templater.py:94} ERROR - Failed to resolve template field '_sql'
Traceback (most recent call last):
  File "/home/airflow/.local/lib/python3.12/site-packages/airflow/template/templater.py", line 92, in resolve_template_files
    setattr(self, field, env.loader.get_source(env, content)[0])  # type: ignore
                         ^^^^^^^^^^^^^^^^^^^^^^^^^^^^^^^^^^^
  File "/home/airflow/.local/lib/python3.12/site-packages/jinja2/loaders.py", line 207, in get_source
    raise TemplateNotFound(template)
jinja2.exceptions.TemplateNotFound: test.sql
[2025-01-16T20:14:28.564+0000] {processor.py:925} INFO - DAG(s) 'test' retrieved from /opt/airflow/dags/test.py
[2025-01-16T20:14:28.582+0000] {logging_mixin.py:190} INFO - [2025-01-16T20:14:28.582+0000] {dag.py:3239} INFO - Sync 1 DAGs
[2025-01-16T20:14:28.594+0000] {logging_mixin.py:190} INFO - [2025-01-16T20:14:28.594+0000] {dag.py:4180} INFO - Setting next_dagrun for test to None, run_after=None
[2025-01-16T20:14:28.621+0000] {processor.py:208} INFO - Processing /opt/airflow/dags/test.py took 0.209 seconds
[2025-01-16T20:14:59.186+0000] {processor.py:186} INFO - Started process (PID=277) to work on /opt/airflow/dags/test.py
[2025-01-16T20:14:59.187+0000] {processor.py:914} INFO - Processing file /opt/airflow/dags/test.py for tasks to queue
[2025-01-16T20:14:59.189+0000] {logging_mixin.py:190} INFO - [2025-01-16T20:14:59.189+0000] {dagbag.py:588} INFO - Filling up the DagBag from /opt/airflow/dags/test.py
[2025-01-16T20:14:59.321+0000] {logging_mixin.py:190} INFO - [2025-01-16T20:14:59.320+0000] {templater.py:94} ERROR - Failed to resolve template field '_sql'
Traceback (most recent call last):
  File "/home/airflow/.local/lib/python3.12/site-packages/airflow/template/templater.py", line 92, in resolve_template_files
    setattr(self, field, env.loader.get_source(env, content)[0])  # type: ignore
                         ^^^^^^^^^^^^^^^^^^^^^^^^^^^^^^^^^^^
  File "/home/airflow/.local/lib/python3.12/site-packages/jinja2/loaders.py", line 207, in get_source
    raise TemplateNotFound(template)
jinja2.exceptions.TemplateNotFound: test.sql
[2025-01-16T20:14:59.323+0000] {processor.py:925} INFO - DAG(s) 'test' retrieved from /opt/airflow/dags/test.py
[2025-01-16T20:14:59.346+0000] {logging_mixin.py:190} INFO - [2025-01-16T20:14:59.346+0000] {dag.py:3239} INFO - Sync 1 DAGs
[2025-01-16T20:14:59.357+0000] {logging_mixin.py:190} INFO - [2025-01-16T20:14:59.357+0000] {dag.py:4180} INFO - Setting next_dagrun for test to None, run_after=None
[2025-01-16T20:14:59.374+0000] {processor.py:208} INFO - Processing /opt/airflow/dags/test.py took 0.192 seconds
[2025-01-16T20:15:29.929+0000] {processor.py:186} INFO - Started process (PID=288) to work on /opt/airflow/dags/test.py
[2025-01-16T20:15:29.930+0000] {processor.py:914} INFO - Processing file /opt/airflow/dags/test.py for tasks to queue
[2025-01-16T20:15:29.933+0000] {logging_mixin.py:190} INFO - [2025-01-16T20:15:29.932+0000] {dagbag.py:588} INFO - Filling up the DagBag from /opt/airflow/dags/test.py
[2025-01-16T20:15:30.074+0000] {logging_mixin.py:190} INFO - [2025-01-16T20:15:30.073+0000] {templater.py:94} ERROR - Failed to resolve template field '_sql'
Traceback (most recent call last):
  File "/home/airflow/.local/lib/python3.12/site-packages/airflow/template/templater.py", line 92, in resolve_template_files
    setattr(self, field, env.loader.get_source(env, content)[0])  # type: ignore
                         ^^^^^^^^^^^^^^^^^^^^^^^^^^^^^^^^^^^
  File "/home/airflow/.local/lib/python3.12/site-packages/jinja2/loaders.py", line 207, in get_source
    raise TemplateNotFound(template)
jinja2.exceptions.TemplateNotFound: test.sql
[2025-01-16T20:15:30.076+0000] {processor.py:925} INFO - DAG(s) 'test' retrieved from /opt/airflow/dags/test.py
[2025-01-16T20:15:30.097+0000] {logging_mixin.py:190} INFO - [2025-01-16T20:15:30.097+0000] {dag.py:3239} INFO - Sync 1 DAGs
[2025-01-16T20:15:30.108+0000] {logging_mixin.py:190} INFO - [2025-01-16T20:15:30.108+0000] {dag.py:4180} INFO - Setting next_dagrun for test to None, run_after=None
[2025-01-16T20:15:30.139+0000] {processor.py:208} INFO - Processing /opt/airflow/dags/test.py took 0.214 seconds
[2025-01-16T20:16:01.077+0000] {processor.py:186} INFO - Started process (PID=299) to work on /opt/airflow/dags/test.py
[2025-01-16T20:16:01.078+0000] {processor.py:914} INFO - Processing file /opt/airflow/dags/test.py for tasks to queue
[2025-01-16T20:16:01.080+0000] {logging_mixin.py:190} INFO - [2025-01-16T20:16:01.080+0000] {dagbag.py:588} INFO - Filling up the DagBag from /opt/airflow/dags/test.py
[2025-01-16T20:16:01.214+0000] {logging_mixin.py:190} INFO - [2025-01-16T20:16:01.213+0000] {templater.py:94} ERROR - Failed to resolve template field '_sql'
Traceback (most recent call last):
  File "/home/airflow/.local/lib/python3.12/site-packages/airflow/template/templater.py", line 92, in resolve_template_files
    setattr(self, field, env.loader.get_source(env, content)[0])  # type: ignore
                         ^^^^^^^^^^^^^^^^^^^^^^^^^^^^^^^^^^^
  File "/home/airflow/.local/lib/python3.12/site-packages/jinja2/loaders.py", line 207, in get_source
    raise TemplateNotFound(template)
jinja2.exceptions.TemplateNotFound: test.sql
[2025-01-16T20:16:01.216+0000] {processor.py:925} INFO - DAG(s) 'test' retrieved from /opt/airflow/dags/test.py
[2025-01-16T20:16:01.235+0000] {logging_mixin.py:190} INFO - [2025-01-16T20:16:01.234+0000] {dag.py:3239} INFO - Sync 1 DAGs
[2025-01-16T20:16:01.245+0000] {logging_mixin.py:190} INFO - [2025-01-16T20:16:01.244+0000] {dag.py:4180} INFO - Setting next_dagrun for test to None, run_after=None
[2025-01-16T20:16:01.264+0000] {processor.py:208} INFO - Processing /opt/airflow/dags/test.py took 0.192 seconds
[2025-01-16T20:16:31.866+0000] {processor.py:186} INFO - Started process (PID=310) to work on /opt/airflow/dags/test.py
[2025-01-16T20:16:31.867+0000] {processor.py:914} INFO - Processing file /opt/airflow/dags/test.py for tasks to queue
[2025-01-16T20:16:31.869+0000] {logging_mixin.py:190} INFO - [2025-01-16T20:16:31.869+0000] {dagbag.py:588} INFO - Filling up the DagBag from /opt/airflow/dags/test.py
[2025-01-16T20:16:32.002+0000] {logging_mixin.py:190} INFO - [2025-01-16T20:16:32.001+0000] {templater.py:94} ERROR - Failed to resolve template field '_sql'
Traceback (most recent call last):
  File "/home/airflow/.local/lib/python3.12/site-packages/airflow/template/templater.py", line 92, in resolve_template_files
    setattr(self, field, env.loader.get_source(env, content)[0])  # type: ignore
                         ^^^^^^^^^^^^^^^^^^^^^^^^^^^^^^^^^^^
  File "/home/airflow/.local/lib/python3.12/site-packages/jinja2/loaders.py", line 207, in get_source
    raise TemplateNotFound(template)
jinja2.exceptions.TemplateNotFound: test.sql
[2025-01-16T20:16:32.004+0000] {processor.py:925} INFO - DAG(s) 'test' retrieved from /opt/airflow/dags/test.py
[2025-01-16T20:16:32.022+0000] {logging_mixin.py:190} INFO - [2025-01-16T20:16:32.022+0000] {dag.py:3239} INFO - Sync 1 DAGs
[2025-01-16T20:16:32.033+0000] {logging_mixin.py:190} INFO - [2025-01-16T20:16:32.033+0000] {dag.py:4180} INFO - Setting next_dagrun for test to None, run_after=None
[2025-01-16T20:16:32.063+0000] {processor.py:208} INFO - Processing /opt/airflow/dags/test.py took 0.202 seconds
[2025-01-16T20:17:02.140+0000] {processor.py:186} INFO - Started process (PID=320) to work on /opt/airflow/dags/test.py
[2025-01-16T20:17:02.141+0000] {processor.py:914} INFO - Processing file /opt/airflow/dags/test.py for tasks to queue
[2025-01-16T20:17:02.143+0000] {logging_mixin.py:190} INFO - [2025-01-16T20:17:02.143+0000] {dagbag.py:588} INFO - Filling up the DagBag from /opt/airflow/dags/test.py
[2025-01-16T20:17:02.327+0000] {logging_mixin.py:190} INFO - [2025-01-16T20:17:02.326+0000] {templater.py:94} ERROR - Failed to resolve template field '_sql'
Traceback (most recent call last):
  File "/home/airflow/.local/lib/python3.12/site-packages/airflow/template/templater.py", line 92, in resolve_template_files
    setattr(self, field, env.loader.get_source(env, content)[0])  # type: ignore
                         ^^^^^^^^^^^^^^^^^^^^^^^^^^^^^^^^^^^
  File "/home/airflow/.local/lib/python3.12/site-packages/jinja2/loaders.py", line 207, in get_source
    raise TemplateNotFound(template)
jinja2.exceptions.TemplateNotFound: test.sql
[2025-01-16T20:17:02.329+0000] {processor.py:925} INFO - DAG(s) 'test' retrieved from /opt/airflow/dags/test.py
[2025-01-16T20:17:02.350+0000] {logging_mixin.py:190} INFO - [2025-01-16T20:17:02.350+0000] {dag.py:3239} INFO - Sync 1 DAGs
[2025-01-16T20:17:02.362+0000] {logging_mixin.py:190} INFO - [2025-01-16T20:17:02.362+0000] {dag.py:4180} INFO - Setting next_dagrun for test to None, run_after=None
[2025-01-16T20:17:02.394+0000] {processor.py:208} INFO - Processing /opt/airflow/dags/test.py took 0.259 seconds
[2025-01-16T20:17:32.611+0000] {processor.py:186} INFO - Started process (PID=332) to work on /opt/airflow/dags/test.py
[2025-01-16T20:17:32.619+0000] {processor.py:914} INFO - Processing file /opt/airflow/dags/test.py for tasks to queue
[2025-01-16T20:17:32.621+0000] {logging_mixin.py:190} INFO - [2025-01-16T20:17:32.621+0000] {dagbag.py:588} INFO - Filling up the DagBag from /opt/airflow/dags/test.py
[2025-01-16T20:17:32.782+0000] {logging_mixin.py:190} INFO - [2025-01-16T20:17:32.781+0000] {templater.py:94} ERROR - Failed to resolve template field '_sql'
Traceback (most recent call last):
  File "/home/airflow/.local/lib/python3.12/site-packages/airflow/template/templater.py", line 92, in resolve_template_files
    setattr(self, field, env.loader.get_source(env, content)[0])  # type: ignore
                         ^^^^^^^^^^^^^^^^^^^^^^^^^^^^^^^^^^^
  File "/home/airflow/.local/lib/python3.12/site-packages/jinja2/loaders.py", line 207, in get_source
    raise TemplateNotFound(template)
jinja2.exceptions.TemplateNotFound: test.sql
[2025-01-16T20:17:32.784+0000] {processor.py:925} INFO - DAG(s) 'test' retrieved from /opt/airflow/dags/test.py
[2025-01-16T20:17:32.806+0000] {logging_mixin.py:190} INFO - [2025-01-16T20:17:32.806+0000] {dag.py:3239} INFO - Sync 1 DAGs
[2025-01-16T20:17:32.820+0000] {logging_mixin.py:190} INFO - [2025-01-16T20:17:32.820+0000] {dag.py:4180} INFO - Setting next_dagrun for test to None, run_after=None
[2025-01-16T20:17:32.854+0000] {processor.py:208} INFO - Processing /opt/airflow/dags/test.py took 0.248 seconds
[2025-01-16T20:18:03.755+0000] {processor.py:186} INFO - Started process (PID=344) to work on /opt/airflow/dags/test.py
[2025-01-16T20:18:03.756+0000] {processor.py:914} INFO - Processing file /opt/airflow/dags/test.py for tasks to queue
[2025-01-16T20:18:03.758+0000] {logging_mixin.py:190} INFO - [2025-01-16T20:18:03.757+0000] {dagbag.py:588} INFO - Filling up the DagBag from /opt/airflow/dags/test.py
[2025-01-16T20:18:03.886+0000] {logging_mixin.py:190} INFO - [2025-01-16T20:18:03.886+0000] {templater.py:94} ERROR - Failed to resolve template field '_sql'
Traceback (most recent call last):
  File "/home/airflow/.local/lib/python3.12/site-packages/airflow/template/templater.py", line 92, in resolve_template_files
    setattr(self, field, env.loader.get_source(env, content)[0])  # type: ignore
                         ^^^^^^^^^^^^^^^^^^^^^^^^^^^^^^^^^^^
  File "/home/airflow/.local/lib/python3.12/site-packages/jinja2/loaders.py", line 207, in get_source
    raise TemplateNotFound(template)
jinja2.exceptions.TemplateNotFound: test.sql
[2025-01-16T20:18:03.888+0000] {processor.py:925} INFO - DAG(s) 'test' retrieved from /opt/airflow/dags/test.py
[2025-01-16T20:18:03.907+0000] {logging_mixin.py:190} INFO - [2025-01-16T20:18:03.907+0000] {dag.py:3239} INFO - Sync 1 DAGs
[2025-01-16T20:18:03.917+0000] {logging_mixin.py:190} INFO - [2025-01-16T20:18:03.917+0000] {dag.py:4180} INFO - Setting next_dagrun for test to None, run_after=None
[2025-01-16T20:18:03.952+0000] {processor.py:208} INFO - Processing /opt/airflow/dags/test.py took 0.202 seconds
[2025-01-16T20:18:34.053+0000] {processor.py:186} INFO - Started process (PID=355) to work on /opt/airflow/dags/test.py
[2025-01-16T20:18:34.054+0000] {processor.py:914} INFO - Processing file /opt/airflow/dags/test.py for tasks to queue
[2025-01-16T20:18:34.057+0000] {logging_mixin.py:190} INFO - [2025-01-16T20:18:34.057+0000] {dagbag.py:588} INFO - Filling up the DagBag from /opt/airflow/dags/test.py
[2025-01-16T20:18:34.224+0000] {logging_mixin.py:190} INFO - [2025-01-16T20:18:34.223+0000] {templater.py:94} ERROR - Failed to resolve template field '_sql'
Traceback (most recent call last):
  File "/home/airflow/.local/lib/python3.12/site-packages/airflow/template/templater.py", line 92, in resolve_template_files
    setattr(self, field, env.loader.get_source(env, content)[0])  # type: ignore
                         ^^^^^^^^^^^^^^^^^^^^^^^^^^^^^^^^^^^
  File "/home/airflow/.local/lib/python3.12/site-packages/jinja2/loaders.py", line 207, in get_source
    raise TemplateNotFound(template)
jinja2.exceptions.TemplateNotFound: test.sql
[2025-01-16T20:18:34.226+0000] {processor.py:925} INFO - DAG(s) 'test' retrieved from /opt/airflow/dags/test.py
[2025-01-16T20:18:34.250+0000] {logging_mixin.py:190} INFO - [2025-01-16T20:18:34.249+0000] {dag.py:3239} INFO - Sync 1 DAGs
[2025-01-16T20:18:34.263+0000] {logging_mixin.py:190} INFO - [2025-01-16T20:18:34.263+0000] {dag.py:4180} INFO - Setting next_dagrun for test to None, run_after=None
[2025-01-16T20:18:34.299+0000] {processor.py:208} INFO - Processing /opt/airflow/dags/test.py took 0.251 seconds
[2025-01-16T20:19:04.455+0000] {processor.py:186} INFO - Started process (PID=366) to work on /opt/airflow/dags/test.py
[2025-01-16T20:19:04.457+0000] {processor.py:914} INFO - Processing file /opt/airflow/dags/test.py for tasks to queue
[2025-01-16T20:19:04.459+0000] {logging_mixin.py:190} INFO - [2025-01-16T20:19:04.459+0000] {dagbag.py:588} INFO - Filling up the DagBag from /opt/airflow/dags/test.py
[2025-01-16T20:19:04.649+0000] {logging_mixin.py:190} INFO - [2025-01-16T20:19:04.648+0000] {templater.py:94} ERROR - Failed to resolve template field '_sql'
Traceback (most recent call last):
  File "/home/airflow/.local/lib/python3.12/site-packages/airflow/template/templater.py", line 92, in resolve_template_files
    setattr(self, field, env.loader.get_source(env, content)[0])  # type: ignore
                         ^^^^^^^^^^^^^^^^^^^^^^^^^^^^^^^^^^^
  File "/home/airflow/.local/lib/python3.12/site-packages/jinja2/loaders.py", line 207, in get_source
    raise TemplateNotFound(template)
jinja2.exceptions.TemplateNotFound: test.sql
[2025-01-16T20:19:04.652+0000] {processor.py:925} INFO - DAG(s) 'test' retrieved from /opt/airflow/dags/test.py
[2025-01-16T20:19:04.683+0000] {logging_mixin.py:190} INFO - [2025-01-16T20:19:04.682+0000] {dag.py:3239} INFO - Sync 1 DAGs
[2025-01-16T20:19:04.700+0000] {logging_mixin.py:190} INFO - [2025-01-16T20:19:04.699+0000] {dag.py:4180} INFO - Setting next_dagrun for test to None, run_after=None
[2025-01-16T20:19:04.726+0000] {processor.py:208} INFO - Processing /opt/airflow/dags/test.py took 0.277 seconds
[2025-01-16T20:19:34.872+0000] {processor.py:186} INFO - Started process (PID=377) to work on /opt/airflow/dags/test.py
[2025-01-16T20:19:34.873+0000] {processor.py:914} INFO - Processing file /opt/airflow/dags/test.py for tasks to queue
[2025-01-16T20:19:34.876+0000] {logging_mixin.py:190} INFO - [2025-01-16T20:19:34.876+0000] {dagbag.py:588} INFO - Filling up the DagBag from /opt/airflow/dags/test.py
[2025-01-16T20:19:35.131+0000] {logging_mixin.py:190} INFO - [2025-01-16T20:19:35.130+0000] {templater.py:94} ERROR - Failed to resolve template field '_sql'
Traceback (most recent call last):
  File "/home/airflow/.local/lib/python3.12/site-packages/airflow/template/templater.py", line 92, in resolve_template_files
    setattr(self, field, env.loader.get_source(env, content)[0])  # type: ignore
                         ^^^^^^^^^^^^^^^^^^^^^^^^^^^^^^^^^^^
  File "/home/airflow/.local/lib/python3.12/site-packages/jinja2/loaders.py", line 207, in get_source
    raise TemplateNotFound(template)
jinja2.exceptions.TemplateNotFound: test.sql
[2025-01-16T20:19:35.134+0000] {processor.py:925} INFO - DAG(s) 'test' retrieved from /opt/airflow/dags/test.py
[2025-01-16T20:19:35.165+0000] {logging_mixin.py:190} INFO - [2025-01-16T20:19:35.165+0000] {dag.py:3239} INFO - Sync 1 DAGs
[2025-01-16T20:19:35.182+0000] {logging_mixin.py:190} INFO - [2025-01-16T20:19:35.181+0000] {dag.py:4180} INFO - Setting next_dagrun for test to None, run_after=None
[2025-01-16T20:19:35.215+0000] {processor.py:208} INFO - Processing /opt/airflow/dags/test.py took 0.349 seconds
[2025-01-16T20:20:06.148+0000] {processor.py:186} INFO - Started process (PID=388) to work on /opt/airflow/dags/test.py
[2025-01-16T20:20:06.148+0000] {processor.py:914} INFO - Processing file /opt/airflow/dags/test.py for tasks to queue
[2025-01-16T20:20:06.151+0000] {logging_mixin.py:190} INFO - [2025-01-16T20:20:06.151+0000] {dagbag.py:588} INFO - Filling up the DagBag from /opt/airflow/dags/test.py
[2025-01-16T20:20:06.310+0000] {logging_mixin.py:190} INFO - [2025-01-16T20:20:06.309+0000] {templater.py:94} ERROR - Failed to resolve template field '_sql'
Traceback (most recent call last):
  File "/home/airflow/.local/lib/python3.12/site-packages/airflow/template/templater.py", line 92, in resolve_template_files
    setattr(self, field, env.loader.get_source(env, content)[0])  # type: ignore
                         ^^^^^^^^^^^^^^^^^^^^^^^^^^^^^^^^^^^
  File "/home/airflow/.local/lib/python3.12/site-packages/jinja2/loaders.py", line 207, in get_source
    raise TemplateNotFound(template)
jinja2.exceptions.TemplateNotFound: test.sql
[2025-01-16T20:20:06.312+0000] {processor.py:925} INFO - DAG(s) 'test' retrieved from /opt/airflow/dags/test.py
[2025-01-16T20:20:06.333+0000] {logging_mixin.py:190} INFO - [2025-01-16T20:20:06.333+0000] {dag.py:3239} INFO - Sync 1 DAGs
[2025-01-16T20:20:06.348+0000] {logging_mixin.py:190} INFO - [2025-01-16T20:20:06.347+0000] {dag.py:4180} INFO - Setting next_dagrun for test to None, run_after=None
[2025-01-16T20:20:06.369+0000] {processor.py:208} INFO - Processing /opt/airflow/dags/test.py took 0.227 seconds
[2025-01-16T20:20:36.495+0000] {processor.py:186} INFO - Started process (PID=399) to work on /opt/airflow/dags/test.py
[2025-01-16T20:20:36.497+0000] {processor.py:914} INFO - Processing file /opt/airflow/dags/test.py for tasks to queue
[2025-01-16T20:20:36.500+0000] {logging_mixin.py:190} INFO - [2025-01-16T20:20:36.499+0000] {dagbag.py:588} INFO - Filling up the DagBag from /opt/airflow/dags/test.py
[2025-01-16T20:20:36.673+0000] {logging_mixin.py:190} INFO - [2025-01-16T20:20:36.673+0000] {templater.py:94} ERROR - Failed to resolve template field '_sql'
Traceback (most recent call last):
  File "/home/airflow/.local/lib/python3.12/site-packages/airflow/template/templater.py", line 92, in resolve_template_files
    setattr(self, field, env.loader.get_source(env, content)[0])  # type: ignore
                         ^^^^^^^^^^^^^^^^^^^^^^^^^^^^^^^^^^^
  File "/home/airflow/.local/lib/python3.12/site-packages/jinja2/loaders.py", line 207, in get_source
    raise TemplateNotFound(template)
jinja2.exceptions.TemplateNotFound: test.sql
[2025-01-16T20:20:36.678+0000] {processor.py:925} INFO - DAG(s) 'test' retrieved from /opt/airflow/dags/test.py
[2025-01-16T20:20:36.704+0000] {logging_mixin.py:190} INFO - [2025-01-16T20:20:36.704+0000] {dag.py:3239} INFO - Sync 1 DAGs
[2025-01-16T20:20:36.720+0000] {logging_mixin.py:190} INFO - [2025-01-16T20:20:36.719+0000] {dag.py:4180} INFO - Setting next_dagrun for test to None, run_after=None
[2025-01-16T20:20:36.756+0000] {processor.py:208} INFO - Processing /opt/airflow/dags/test.py took 0.267 seconds
[2025-01-16T20:21:06.915+0000] {processor.py:186} INFO - Started process (PID=410) to work on /opt/airflow/dags/test.py
[2025-01-16T20:21:06.920+0000] {processor.py:914} INFO - Processing file /opt/airflow/dags/test.py for tasks to queue
[2025-01-16T20:21:06.925+0000] {logging_mixin.py:190} INFO - [2025-01-16T20:21:06.925+0000] {dagbag.py:588} INFO - Filling up the DagBag from /opt/airflow/dags/test.py
[2025-01-16T20:21:07.095+0000] {logging_mixin.py:190} INFO - [2025-01-16T20:21:07.093+0000] {templater.py:94} ERROR - Failed to resolve template field '_sql'
Traceback (most recent call last):
  File "/home/airflow/.local/lib/python3.12/site-packages/airflow/template/templater.py", line 92, in resolve_template_files
    setattr(self, field, env.loader.get_source(env, content)[0])  # type: ignore
                         ^^^^^^^^^^^^^^^^^^^^^^^^^^^^^^^^^^^
  File "/home/airflow/.local/lib/python3.12/site-packages/jinja2/loaders.py", line 207, in get_source
    raise TemplateNotFound(template)
jinja2.exceptions.TemplateNotFound: test.sql
[2025-01-16T20:21:07.098+0000] {processor.py:925} INFO - DAG(s) 'test' retrieved from /opt/airflow/dags/test.py
[2025-01-16T20:21:07.123+0000] {logging_mixin.py:190} INFO - [2025-01-16T20:21:07.122+0000] {dag.py:3239} INFO - Sync 1 DAGs
[2025-01-16T20:21:07.138+0000] {logging_mixin.py:190} INFO - [2025-01-16T20:21:07.138+0000] {dag.py:4180} INFO - Setting next_dagrun for test to None, run_after=None
[2025-01-16T20:21:07.175+0000] {processor.py:208} INFO - Processing /opt/airflow/dags/test.py took 0.266 seconds
[2025-01-16T20:21:37.480+0000] {processor.py:186} INFO - Started process (PID=421) to work on /opt/airflow/dags/test.py
[2025-01-16T20:21:37.481+0000] {processor.py:914} INFO - Processing file /opt/airflow/dags/test.py for tasks to queue
[2025-01-16T20:21:37.484+0000] {logging_mixin.py:190} INFO - [2025-01-16T20:21:37.484+0000] {dagbag.py:588} INFO - Filling up the DagBag from /opt/airflow/dags/test.py
[2025-01-16T20:21:37.654+0000] {logging_mixin.py:190} INFO - [2025-01-16T20:21:37.653+0000] {templater.py:94} ERROR - Failed to resolve template field '_sql'
Traceback (most recent call last):
  File "/home/airflow/.local/lib/python3.12/site-packages/airflow/template/templater.py", line 92, in resolve_template_files
    setattr(self, field, env.loader.get_source(env, content)[0])  # type: ignore
                         ^^^^^^^^^^^^^^^^^^^^^^^^^^^^^^^^^^^
  File "/home/airflow/.local/lib/python3.12/site-packages/jinja2/loaders.py", line 207, in get_source
    raise TemplateNotFound(template)
jinja2.exceptions.TemplateNotFound: test.sql
[2025-01-16T20:21:37.656+0000] {processor.py:925} INFO - DAG(s) 'test' retrieved from /opt/airflow/dags/test.py
[2025-01-16T20:21:37.682+0000] {logging_mixin.py:190} INFO - [2025-01-16T20:21:37.682+0000] {dag.py:3239} INFO - Sync 1 DAGs
[2025-01-16T20:21:37.697+0000] {logging_mixin.py:190} INFO - [2025-01-16T20:21:37.696+0000] {dag.py:4180} INFO - Setting next_dagrun for test to None, run_after=None
[2025-01-16T20:21:37.737+0000] {processor.py:208} INFO - Processing /opt/airflow/dags/test.py took 0.264 seconds
[2025-01-16T20:22:08.161+0000] {processor.py:186} INFO - Started process (PID=431) to work on /opt/airflow/dags/test.py
[2025-01-16T20:22:08.162+0000] {processor.py:914} INFO - Processing file /opt/airflow/dags/test.py for tasks to queue
[2025-01-16T20:22:08.164+0000] {logging_mixin.py:190} INFO - [2025-01-16T20:22:08.164+0000] {dagbag.py:588} INFO - Filling up the DagBag from /opt/airflow/dags/test.py
[2025-01-16T20:22:08.316+0000] {logging_mixin.py:190} INFO - [2025-01-16T20:22:08.315+0000] {templater.py:94} ERROR - Failed to resolve template field '_sql'
Traceback (most recent call last):
  File "/home/airflow/.local/lib/python3.12/site-packages/airflow/template/templater.py", line 92, in resolve_template_files
    setattr(self, field, env.loader.get_source(env, content)[0])  # type: ignore
                         ^^^^^^^^^^^^^^^^^^^^^^^^^^^^^^^^^^^
  File "/home/airflow/.local/lib/python3.12/site-packages/jinja2/loaders.py", line 207, in get_source
    raise TemplateNotFound(template)
jinja2.exceptions.TemplateNotFound: test.sql
[2025-01-16T20:22:08.318+0000] {processor.py:925} INFO - DAG(s) 'test' retrieved from /opt/airflow/dags/test.py
[2025-01-16T20:22:08.340+0000] {logging_mixin.py:190} INFO - [2025-01-16T20:22:08.340+0000] {dag.py:3239} INFO - Sync 1 DAGs
[2025-01-16T20:22:08.351+0000] {logging_mixin.py:190} INFO - [2025-01-16T20:22:08.350+0000] {dag.py:4180} INFO - Setting next_dagrun for test to None, run_after=None
[2025-01-16T20:22:08.374+0000] {processor.py:208} INFO - Processing /opt/airflow/dags/test.py took 0.219 seconds
[2025-01-16T20:22:38.845+0000] {processor.py:186} INFO - Started process (PID=442) to work on /opt/airflow/dags/test.py
[2025-01-16T20:22:38.846+0000] {processor.py:914} INFO - Processing file /opt/airflow/dags/test.py for tasks to queue
[2025-01-16T20:22:38.848+0000] {logging_mixin.py:190} INFO - [2025-01-16T20:22:38.848+0000] {dagbag.py:588} INFO - Filling up the DagBag from /opt/airflow/dags/test.py
[2025-01-16T20:22:39.000+0000] {logging_mixin.py:190} INFO - [2025-01-16T20:22:38.999+0000] {templater.py:94} ERROR - Failed to resolve template field '_sql'
Traceback (most recent call last):
  File "/home/airflow/.local/lib/python3.12/site-packages/airflow/template/templater.py", line 92, in resolve_template_files
    setattr(self, field, env.loader.get_source(env, content)[0])  # type: ignore
                         ^^^^^^^^^^^^^^^^^^^^^^^^^^^^^^^^^^^
  File "/home/airflow/.local/lib/python3.12/site-packages/jinja2/loaders.py", line 207, in get_source
    raise TemplateNotFound(template)
jinja2.exceptions.TemplateNotFound: test.sql
[2025-01-16T20:22:39.002+0000] {processor.py:925} INFO - DAG(s) 'test' retrieved from /opt/airflow/dags/test.py
[2025-01-16T20:22:39.023+0000] {logging_mixin.py:190} INFO - [2025-01-16T20:22:39.022+0000] {dag.py:3239} INFO - Sync 1 DAGs
[2025-01-16T20:22:39.037+0000] {logging_mixin.py:190} INFO - [2025-01-16T20:22:39.037+0000] {dag.py:4180} INFO - Setting next_dagrun for test to None, run_after=None
[2025-01-16T20:22:39.074+0000] {processor.py:208} INFO - Processing /opt/airflow/dags/test.py took 0.234 seconds
[2025-01-16T20:23:09.368+0000] {processor.py:186} INFO - Started process (PID=453) to work on /opt/airflow/dags/test.py
[2025-01-16T20:23:09.369+0000] {processor.py:914} INFO - Processing file /opt/airflow/dags/test.py for tasks to queue
[2025-01-16T20:23:09.372+0000] {logging_mixin.py:190} INFO - [2025-01-16T20:23:09.372+0000] {dagbag.py:588} INFO - Filling up the DagBag from /opt/airflow/dags/test.py
[2025-01-16T20:23:09.540+0000] {logging_mixin.py:190} INFO - [2025-01-16T20:23:09.538+0000] {templater.py:94} ERROR - Failed to resolve template field '_sql'
Traceback (most recent call last):
  File "/home/airflow/.local/lib/python3.12/site-packages/airflow/template/templater.py", line 92, in resolve_template_files
    setattr(self, field, env.loader.get_source(env, content)[0])  # type: ignore
                         ^^^^^^^^^^^^^^^^^^^^^^^^^^^^^^^^^^^
  File "/home/airflow/.local/lib/python3.12/site-packages/jinja2/loaders.py", line 207, in get_source
    raise TemplateNotFound(template)
jinja2.exceptions.TemplateNotFound: test.sql
[2025-01-16T20:23:09.543+0000] {processor.py:925} INFO - DAG(s) 'test' retrieved from /opt/airflow/dags/test.py
[2025-01-16T20:23:09.569+0000] {logging_mixin.py:190} INFO - [2025-01-16T20:23:09.568+0000] {dag.py:3239} INFO - Sync 1 DAGs
[2025-01-16T20:23:09.584+0000] {logging_mixin.py:190} INFO - [2025-01-16T20:23:09.584+0000] {dag.py:4180} INFO - Setting next_dagrun for test to None, run_after=None
[2025-01-16T20:23:09.624+0000] {processor.py:208} INFO - Processing /opt/airflow/dags/test.py took 0.262 seconds
[2025-01-16T20:23:39.817+0000] {processor.py:186} INFO - Started process (PID=464) to work on /opt/airflow/dags/test.py
[2025-01-16T20:23:39.818+0000] {processor.py:914} INFO - Processing file /opt/airflow/dags/test.py for tasks to queue
[2025-01-16T20:23:39.820+0000] {logging_mixin.py:190} INFO - [2025-01-16T20:23:39.820+0000] {dagbag.py:588} INFO - Filling up the DagBag from /opt/airflow/dags/test.py
[2025-01-16T20:23:39.967+0000] {logging_mixin.py:190} INFO - [2025-01-16T20:23:39.966+0000] {templater.py:94} ERROR - Failed to resolve template field '_sql'
Traceback (most recent call last):
  File "/home/airflow/.local/lib/python3.12/site-packages/airflow/template/templater.py", line 92, in resolve_template_files
    setattr(self, field, env.loader.get_source(env, content)[0])  # type: ignore
                         ^^^^^^^^^^^^^^^^^^^^^^^^^^^^^^^^^^^
  File "/home/airflow/.local/lib/python3.12/site-packages/jinja2/loaders.py", line 207, in get_source
    raise TemplateNotFound(template)
jinja2.exceptions.TemplateNotFound: test.sql
[2025-01-16T20:23:39.969+0000] {processor.py:925} INFO - DAG(s) 'test' retrieved from /opt/airflow/dags/test.py
[2025-01-16T20:23:39.993+0000] {logging_mixin.py:190} INFO - [2025-01-16T20:23:39.992+0000] {dag.py:3239} INFO - Sync 1 DAGs
[2025-01-16T20:23:40.004+0000] {logging_mixin.py:190} INFO - [2025-01-16T20:23:40.003+0000] {dag.py:4180} INFO - Setting next_dagrun for test to None, run_after=None
[2025-01-16T20:23:40.090+0000] {processor.py:208} INFO - Processing /opt/airflow/dags/test.py took 0.278 seconds
[2025-01-16T20:24:10.889+0000] {processor.py:186} INFO - Started process (PID=475) to work on /opt/airflow/dags/test.py
[2025-01-16T20:24:10.890+0000] {processor.py:914} INFO - Processing file /opt/airflow/dags/test.py for tasks to queue
[2025-01-16T20:24:10.891+0000] {logging_mixin.py:190} INFO - [2025-01-16T20:24:10.891+0000] {dagbag.py:588} INFO - Filling up the DagBag from /opt/airflow/dags/test.py
[2025-01-16T20:24:11.026+0000] {logging_mixin.py:190} INFO - [2025-01-16T20:24:11.026+0000] {templater.py:94} ERROR - Failed to resolve template field '_sql'
Traceback (most recent call last):
  File "/home/airflow/.local/lib/python3.12/site-packages/airflow/template/templater.py", line 92, in resolve_template_files
    setattr(self, field, env.loader.get_source(env, content)[0])  # type: ignore
                         ^^^^^^^^^^^^^^^^^^^^^^^^^^^^^^^^^^^
  File "/home/airflow/.local/lib/python3.12/site-packages/jinja2/loaders.py", line 207, in get_source
    raise TemplateNotFound(template)
jinja2.exceptions.TemplateNotFound: test.sql
[2025-01-16T20:24:11.028+0000] {processor.py:925} INFO - DAG(s) 'test' retrieved from /opt/airflow/dags/test.py
[2025-01-16T20:24:11.045+0000] {logging_mixin.py:190} INFO - [2025-01-16T20:24:11.045+0000] {dag.py:3239} INFO - Sync 1 DAGs
[2025-01-16T20:24:11.056+0000] {logging_mixin.py:190} INFO - [2025-01-16T20:24:11.056+0000] {dag.py:4180} INFO - Setting next_dagrun for test to None, run_after=None
[2025-01-16T20:24:11.090+0000] {processor.py:208} INFO - Processing /opt/airflow/dags/test.py took 0.206 seconds
[2025-01-16T20:24:41.289+0000] {processor.py:186} INFO - Started process (PID=486) to work on /opt/airflow/dags/test.py
[2025-01-16T20:24:41.290+0000] {processor.py:914} INFO - Processing file /opt/airflow/dags/test.py for tasks to queue
[2025-01-16T20:24:41.292+0000] {logging_mixin.py:190} INFO - [2025-01-16T20:24:41.292+0000] {dagbag.py:588} INFO - Filling up the DagBag from /opt/airflow/dags/test.py
[2025-01-16T20:24:41.427+0000] {logging_mixin.py:190} INFO - [2025-01-16T20:24:41.426+0000] {templater.py:94} ERROR - Failed to resolve template field '_sql'
Traceback (most recent call last):
  File "/home/airflow/.local/lib/python3.12/site-packages/airflow/template/templater.py", line 92, in resolve_template_files
    setattr(self, field, env.loader.get_source(env, content)[0])  # type: ignore
                         ^^^^^^^^^^^^^^^^^^^^^^^^^^^^^^^^^^^
  File "/home/airflow/.local/lib/python3.12/site-packages/jinja2/loaders.py", line 207, in get_source
    raise TemplateNotFound(template)
jinja2.exceptions.TemplateNotFound: test.sql
[2025-01-16T20:24:41.432+0000] {processor.py:925} INFO - DAG(s) 'test' retrieved from /opt/airflow/dags/test.py
[2025-01-16T20:24:41.450+0000] {logging_mixin.py:190} INFO - [2025-01-16T20:24:41.450+0000] {dag.py:3239} INFO - Sync 1 DAGs
[2025-01-16T20:24:41.461+0000] {logging_mixin.py:190} INFO - [2025-01-16T20:24:41.461+0000] {dag.py:4180} INFO - Setting next_dagrun for test to None, run_after=None
[2025-01-16T20:24:41.496+0000] {processor.py:208} INFO - Processing /opt/airflow/dags/test.py took 0.211 seconds
[2025-01-16T20:25:12.360+0000] {processor.py:186} INFO - Started process (PID=496) to work on /opt/airflow/dags/test.py
[2025-01-16T20:25:12.361+0000] {processor.py:914} INFO - Processing file /opt/airflow/dags/test.py for tasks to queue
[2025-01-16T20:25:12.364+0000] {logging_mixin.py:190} INFO - [2025-01-16T20:25:12.364+0000] {dagbag.py:588} INFO - Filling up the DagBag from /opt/airflow/dags/test.py
[2025-01-16T20:25:12.516+0000] {logging_mixin.py:190} INFO - [2025-01-16T20:25:12.515+0000] {templater.py:94} ERROR - Failed to resolve template field '_sql'
Traceback (most recent call last):
  File "/home/airflow/.local/lib/python3.12/site-packages/airflow/template/templater.py", line 92, in resolve_template_files
    setattr(self, field, env.loader.get_source(env, content)[0])  # type: ignore
                         ^^^^^^^^^^^^^^^^^^^^^^^^^^^^^^^^^^^
  File "/home/airflow/.local/lib/python3.12/site-packages/jinja2/loaders.py", line 207, in get_source
    raise TemplateNotFound(template)
jinja2.exceptions.TemplateNotFound: test.sql
[2025-01-16T20:25:12.519+0000] {processor.py:925} INFO - DAG(s) 'test' retrieved from /opt/airflow/dags/test.py
[2025-01-16T20:25:12.547+0000] {logging_mixin.py:190} INFO - [2025-01-16T20:25:12.546+0000] {dag.py:3239} INFO - Sync 1 DAGs
[2025-01-16T20:25:12.563+0000] {logging_mixin.py:190} INFO - [2025-01-16T20:25:12.563+0000] {dag.py:4180} INFO - Setting next_dagrun for test to None, run_after=None
[2025-01-16T20:25:12.590+0000] {processor.py:208} INFO - Processing /opt/airflow/dags/test.py took 0.234 seconds
[2025-01-16T20:25:43.259+0000] {processor.py:186} INFO - Started process (PID=507) to work on /opt/airflow/dags/test.py
[2025-01-16T20:25:43.259+0000] {processor.py:914} INFO - Processing file /opt/airflow/dags/test.py for tasks to queue
[2025-01-16T20:25:43.262+0000] {logging_mixin.py:190} INFO - [2025-01-16T20:25:43.262+0000] {dagbag.py:588} INFO - Filling up the DagBag from /opt/airflow/dags/test.py
[2025-01-16T20:25:43.403+0000] {logging_mixin.py:190} INFO - [2025-01-16T20:25:43.402+0000] {templater.py:94} ERROR - Failed to resolve template field '_sql'
Traceback (most recent call last):
  File "/home/airflow/.local/lib/python3.12/site-packages/airflow/template/templater.py", line 92, in resolve_template_files
    setattr(self, field, env.loader.get_source(env, content)[0])  # type: ignore
                         ^^^^^^^^^^^^^^^^^^^^^^^^^^^^^^^^^^^
  File "/home/airflow/.local/lib/python3.12/site-packages/jinja2/loaders.py", line 207, in get_source
    raise TemplateNotFound(template)
jinja2.exceptions.TemplateNotFound: test.sql
[2025-01-16T20:25:43.412+0000] {processor.py:925} INFO - DAG(s) 'test' retrieved from /opt/airflow/dags/test.py
[2025-01-16T20:25:43.432+0000] {logging_mixin.py:190} INFO - [2025-01-16T20:25:43.431+0000] {dag.py:3239} INFO - Sync 1 DAGs
[2025-01-16T20:25:43.443+0000] {logging_mixin.py:190} INFO - [2025-01-16T20:25:43.442+0000] {dag.py:4180} INFO - Setting next_dagrun for test to None, run_after=None
[2025-01-16T20:25:43.473+0000] {processor.py:208} INFO - Processing /opt/airflow/dags/test.py took 0.219 seconds
[2025-01-16T20:26:14.324+0000] {processor.py:186} INFO - Started process (PID=519) to work on /opt/airflow/dags/test.py
[2025-01-16T20:26:14.325+0000] {processor.py:914} INFO - Processing file /opt/airflow/dags/test.py for tasks to queue
[2025-01-16T20:26:14.327+0000] {logging_mixin.py:190} INFO - [2025-01-16T20:26:14.327+0000] {dagbag.py:588} INFO - Filling up the DagBag from /opt/airflow/dags/test.py
[2025-01-16T20:26:14.463+0000] {logging_mixin.py:190} INFO - [2025-01-16T20:26:14.462+0000] {templater.py:94} ERROR - Failed to resolve template field '_sql'
Traceback (most recent call last):
  File "/home/airflow/.local/lib/python3.12/site-packages/airflow/template/templater.py", line 92, in resolve_template_files
    setattr(self, field, env.loader.get_source(env, content)[0])  # type: ignore
                         ^^^^^^^^^^^^^^^^^^^^^^^^^^^^^^^^^^^
  File "/home/airflow/.local/lib/python3.12/site-packages/jinja2/loaders.py", line 207, in get_source
    raise TemplateNotFound(template)
jinja2.exceptions.TemplateNotFound: test.sql
[2025-01-16T20:26:14.465+0000] {processor.py:925} INFO - DAG(s) 'test' retrieved from /opt/airflow/dags/test.py
[2025-01-16T20:26:14.484+0000] {logging_mixin.py:190} INFO - [2025-01-16T20:26:14.484+0000] {dag.py:3239} INFO - Sync 1 DAGs
[2025-01-16T20:26:14.496+0000] {logging_mixin.py:190} INFO - [2025-01-16T20:26:14.496+0000] {dag.py:4180} INFO - Setting next_dagrun for test to None, run_after=None
[2025-01-16T20:26:14.528+0000] {processor.py:208} INFO - Processing /opt/airflow/dags/test.py took 0.208 seconds
[2025-01-16T20:26:44.973+0000] {processor.py:186} INFO - Started process (PID=530) to work on /opt/airflow/dags/test.py
[2025-01-16T20:26:44.974+0000] {processor.py:914} INFO - Processing file /opt/airflow/dags/test.py for tasks to queue
[2025-01-16T20:26:44.976+0000] {logging_mixin.py:190} INFO - [2025-01-16T20:26:44.976+0000] {dagbag.py:588} INFO - Filling up the DagBag from /opt/airflow/dags/test.py
[2025-01-16T20:26:45.136+0000] {logging_mixin.py:190} INFO - [2025-01-16T20:26:45.135+0000] {templater.py:94} ERROR - Failed to resolve template field '_sql'
Traceback (most recent call last):
  File "/home/airflow/.local/lib/python3.12/site-packages/airflow/template/templater.py", line 92, in resolve_template_files
    setattr(self, field, env.loader.get_source(env, content)[0])  # type: ignore
                         ^^^^^^^^^^^^^^^^^^^^^^^^^^^^^^^^^^^
  File "/home/airflow/.local/lib/python3.12/site-packages/jinja2/loaders.py", line 207, in get_source
    raise TemplateNotFound(template)
jinja2.exceptions.TemplateNotFound: test.sql
[2025-01-16T20:26:45.138+0000] {processor.py:925} INFO - DAG(s) 'test' retrieved from /opt/airflow/dags/test.py
[2025-01-16T20:26:45.159+0000] {logging_mixin.py:190} INFO - [2025-01-16T20:26:45.158+0000] {dag.py:3239} INFO - Sync 1 DAGs
[2025-01-16T20:26:45.171+0000] {logging_mixin.py:190} INFO - [2025-01-16T20:26:45.170+0000] {dag.py:4180} INFO - Setting next_dagrun for test to None, run_after=None
[2025-01-16T20:26:45.220+0000] {processor.py:208} INFO - Processing /opt/airflow/dags/test.py took 0.252 seconds
